Workbook
Name DMB: #REF!

Sheet MPR Review
C2: Month | D2: 46023
C4: ="Current Month-Year " & ":" & TEXT(TODAY(),"YYYY-MM") -> Current Month-Year :2026-09
A5: Strategic Imperative | C5: Mandatory Outcome KPIs | D5: Meric Owner MT | E5: Definition | F5: Operators | G5: AOP 2025 | H5: Units | I5: Metric Nature | J5: Frequency | K5: Target Actual | L5: Jan | M5: Feb | N5: Q1 | O5: Apr | P5: May | Q5: Q2 | R5: Jul | S5: Aug | T5: Q3 | U5: Oct | V5: Nov | W5: Dec | X5: If reported Red then Cause and Actions | Y5: Consecutive Red more han 2 instance please submit PRIDE | Z5: Consecutive Red more than 2 instance and only for PS&Qmetrics share CAPA | AA5: Next Update/Closure timeline DD-MM
A7: 1. Patient Safety & Quality | C7: =IF('1.Quality'!A6<>"",'1.Quality'!A6,"") -> % CAPA Investigations Currently ≤ 90 days | D7: Neena S | E7: =IF('1.Quality'!B6<>"",'1.Quality'!B6,"") -> Timeliness of investigations | F7: =IF('1.Quality'!C6<>"",'1.Quality'!C6,"") -> >= | G7: =IF('1.Quality'!D6<>"",'1.Quality'!D6,"") -> 90 | H7: =IF('1.Quality'!E6<>"",'1.Quality'!E6,"") -> % | I7: =IF('1.Quality'!F6<>"",'1.Quality'!F6,"") -> Higher the better | J7: =IF('1.Quality'!G6<>"",'1.Quality'!G6,"") -> Monthly | K7: Target | L7: =IF('1.Quality'!I24<>"",'1.Quality'!I24,"") -> 0 | M7: =IF('1.Quality'!J24<>"",'1.Quality'!J24,"") -> 0 | N7: =IF('1.Quality'!K24<>"",'1.Quality'!K24,"") -> 0 | O7: =IF('1.Quality'!L24<>"",'1.Quality'!L24,"") -> 0 | P7: =IF('1.Quality'!M24<>"",'1.Quality'!M24,"") -> 0 | Q7: =IF('1.Quality'!N24<>"",'1.Quality'!N24,"") -> 0 | R7: =IF('1.Quality'!O24<>"",'1.Quality'!O24,"") -> 0 | S7: =IF('1.Quality'!P24<>"",'1.Quality'!P24,"") -> 0 | ... W7: =IF('1.Quality'!T24<>"",'1.Quality'!T24,"") -> 0
K8: Actual | L8: =IF('1.Quality'!I25<>"",'1.Quality'!I25,"") -> 0 | M8: =IF('1.Quality'!J25<>"",'1.Quality'!J25,"") -> 0 | N8: =IF('1.Quality'!K25<>"",'1.Quality'!K25,"") -> 0 | O8: =IF('1.Quality'!L25<>"",'1.Quality'!L25,"") -> 0 | P8: =IF('1.Quality'!M25<>"",'1.Quality'!M25,"") -> 0 | Q8: =IF('1.Quality'!N25<>"",'1.Quality'!N25,"") -> 0 | R8: =IF('1.Quality'!O25<>"",'1.Quality'!O25,"") -> 0 | S8: =IF('1.Quality'!P25<>"",'1.Quality'!P25,"") -> 0 | ... W8: =IF('1.Quality'!T25<>"",'1.Quality'!T25,"")
C9: =IF('1.Quality'!A8<>"",'1.Quality'!A8,"") -> % Complaints Open > 90 days | D9: Neena S | E9: =IF('1.Quality'!B8<>"",'1.Quality'!B8,"") -> Measures complaint closures | F9: =IF('1.Quality'!C8<>"",'1.Quality'!C8,"") -> <= | G9: =IF('1.Quality'!D8<>"",'1.Quality'!D8,"") -> Q1 (8%), Q2 (7%) Q3 (6%) Q4 (5%) | H9: =IF('1.Quality'!E8<>"",'1.Quality'!E8,"") -> % | I9: =IF('1.Quality'!F8<>"",'1.Quality'!F8,"") -> Lower the better | J9: =IF('1.Quality'!G8<>"",'1.Quality'!G8,"") -> Monthly | K9: Target | L9: =IF('1.Quality'!I6<>"",'1.Quality'!I6,"") -> 0.9 | M9: =IF('1.Quality'!J6<>"",'1.Quality'!J6,"") -> 0.9 | N9: =IF('1.Quality'!K6<>"",'1.Quality'!K6,"") -> 0.9 | O9: =IF('1.Quality'!L6<>"",'1.Quality'!L6,"") -> 0.9 | P9: =IF('1.Quality'!M6<>"",'1.Quality'!M6,"") -> 0.9 | Q9: =IF('1.Quality'!N6<>"",'1.Quality'!N6,"") -> 0.9 | R9: =IF('1.Quality'!O6<>"",'1.Quality'!O6,"") -> 0.9 | S9: =IF('1.Quality'!P6<>"",'1.Quality'!P6,"") -> 0.9 | ... W9: =IF('1.Quality'!T6<>"",'1.Quality'!T6,"") -> 0.9
K10: Actual | L10: =IF('1.Quality'!I7<>"",'1.Quality'!I7,"") -> 1 | M10: =IF('1.Quality'!J7<>"",'1.Quality'!J7,"") -> 0.75 | N10: =IF('1.Quality'!K7<>"",'1.Quality'!K7,"") -> 0.4 | O10: =IF('1.Quality'!L7<>"",'1.Quality'!L7,"") -> 0 | P10: =IF('1.Quality'!M7<>"",'1.Quality'!M7,"") -> 0 | Q10: =IF('1.Quality'!N7<>"",'1.Quality'!N7,"") -> 0 | R10: =IF('1.Quality'!O7<>"",'1.Quality'!O7,"") -> 1 | S10: =IF('1.Quality'!P7<>"",'1.Quality'!P7,"") -> 1 | ... W10: =IF('1.Quality'!T7<>"",'1.Quality'!T7,"")
C11: =IF('1.Quality'!A16<>"",'1.Quality'!A16,"") -> C&R > Global Due date | D11: Neena S | E11: =IF('1.Quality'!B16<>"",'1.Quality'!B16,"") -> # of C&Rs that are open beyond plan in market | F11: =IF('1.Quality'!C16<>"",'1.Quality'!C16,"") -> <= | G11: =IF('1.Quality'!D16<>"",'1.Quality'!D16,"") -> 3 | H11: =IF('1.Quality'!E16<>"",'1.Quality'!E16,"") -> No. | I11: =IF('1.Quality'!F16<>"",'1.Quality'!F16,"") -> Lower the better | J11: =IF('1.Quality'!G16<>"",'1.Quality'!G16,"") -> Monthly | K11: Target | L11: =IF('1.Quality'!I8<>"",'1.Quality'!I8,"") -> 0.08 | M11: =IF('1.Quality'!J8<>"",'1.Quality'!J8,"") -> 0.08 | N11: =IF('1.Quality'!K8<>"",'1.Quality'!K8,"") -> 0.08 | O11: =IF('1.Quality'!L8<>"",'1.Quality'!L8,"") -> 0.07 | P11: =IF('1.Quality'!M8<>"",'1.Quality'!M8,"") -> 0.07 | Q11: =IF('1.Quality'!N8<>"",'1.Quality'!N8,"") -> 0.07 | R11: =IF('1.Quality'!O8<>"",'1.Quality'!O8,"") -> 0.06 | S11: =IF('1.Quality'!P8<>"",'1.Quality'!P8,"") -> 0.06 | ... W11: =IF('1.Quality'!T8<>"",'1.Quality'!T8,"") -> 0.05
K12: Actual | L12: =IF('1.Quality'!I9<>"",'1.Quality'!I9,"") -> 0.038 | M12: =IF('1.Quality'!J9<>"",'1.Quality'!J9,"") -> 0.038 | N12: =IF('1.Quality'!K9<>"",'1.Quality'!K9,"") -> 0.028 | O12: =IF('1.Quality'!L9<>"",'1.Quality'!L9,"") -> 0.026 | P12: =IF('1.Quality'!M9<>"",'1.Quality'!M9,"") -> 0.026 | Q12: =IF('1.Quality'!N9<>"",'1.Quality'!N9,"") -> 0.03 | R12: =IF('1.Quality'!O9<>"",'1.Quality'!O9,"") -> 0.03 | S12: =IF('1.Quality'!P9<>"",'1.Quality'!P9,"") -> 0.035 | ... W12: =IF('1.Quality'!T9<>"",'1.Quality'!T9,"")
C13: =IF('2.Regulatory'!A6<>"",'2.Regulatory'!A6,"") -> Registrations & re-certifications on time | D13: Sumit K | E13: =IF('2.Regulatory'!B6<>"",'2.Regulatory'!B6,"") -> (Registration approvals and renewals completed on time) *100/ Total number of approvals planned for the month | F13: =IF('2.Regulatory'!C6<>"",'2.Regulatory'!C6,"") -> >= | G13: =IF('2.Regulatory'!D6<>"",'2.Regulatory'!D6,"") -> 0.97 | H13: =IF('2.Regulatory'!E6<>"",'2.Regulatory'!E6,"") -> % | I13: =IF('2.Regulatory'!F6<>"",'2.Regulatory'!F6,"") -> Higher the better | J13: =IF('2.Regulatory'!G6<>"",'2.Regulatory'!G6,"") -> Monthly | K13: Target | L13: =IF('2.Regulatory'!I6<>"",'2.Regulatory'!I6,"") -> 0.97 | M13: =IF('2.Regulatory'!J6<>"",'2.Regulatory'!J6,"") -> 0.97 | N13: =IF('2.Regulatory'!K6<>"",'2.Regulatory'!K6,"") -> 0.97 | O13: =IF('2.Regulatory'!L6<>"",'2.Regulatory'!L6,"") -> 0.97 | P13: =IF('2.Regulatory'!M6<>"",'2.Regulatory'!M6,"") -> 0.97 | Q13: =IF('2.Regulatory'!N6<>"",'2.Regulatory'!N6,"") -> 0.97 | R13: =IF('2.Regulatory'!O6<>"",'2.Regulatory'!O6,"") -> 0.97 | S13: =IF('2.Regulatory'!P6<>"",'2.Regulatory'!P6,"") -> 0.97 | ... W13: =IF('2.Regulatory'!T6<>"",'2.Regulatory'!T6,"") -> 0.97
K14: Actual | L14: =IF('2.Regulatory'!I7<>"",'2.Regulatory'!I7,"") -> 1 | M14: =IF('2.Regulatory'!J7<>"",'2.Regulatory'!J7,"") -> 1 | N14: =IF('2.Regulatory'!K7<>"",'2.Regulatory'!K7,"") -> 1 | O14: =IF('2.Regulatory'!L7<>"",'2.Regulatory'!L7,"") -> 0.66666667 | P14: =IF('2.Regulatory'!M7<>"",'2.Regulatory'!M7,"") -> 1 | Q14: =IF('2.Regulatory'!N7<>"",'2.Regulatory'!N7,"") -> 1 | R14: =IF('2.Regulatory'!O7<>"",'2.Regulatory'!O7,"") -> 1 | S14: =IF('2.Regulatory'!P7<>"",'2.Regulatory'!P7,"") -> 1 | ... W14: =IF('2.Regulatory'!T7<>"",'2.Regulatory'!T7,"")
C15: =IF('2.Regulatory'!A10<>"",'2.Regulatory'!A10,"") -> Submission on Time | D15: Sumit K | E15: =IF('2.Regulatory'!B10<>"",'2.Regulatory'!B10,"") -> (Regulatory submissions executed on time) *100/ Total number of submissions planned for the month | F15: =IF('2.Regulatory'!C10<>"",'2.Regulatory'!C10,"") -> >= | G15: =IF('2.Regulatory'!D10<>"",'2.Regulatory'!D10,"") -> 1 | H15: =IF('2.Regulatory'!E10<>"",'2.Regulatory'!E10,"") -> % | I15: =IF('2.Regulatory'!F10<>"",'2.Regulatory'!F10,"") -> Higher the better | J15: =IF('2.Regulatory'!G10<>"",'2.Regulatory'!G10,"") -> Monthly | K15: Target | L15: =IF('2.Regulatory'!I10<>"",'2.Regulatory'!I10,"") -> 1 | M15: =IF('2.Regulatory'!J10<>"",'2.Regulatory'!J10,"") -> 1 | N15: =IF('2.Regulatory'!K10<>"",'2.Regulatory'!K10,"") -> 1 | O15: =IF('2.Regulatory'!L10<>"",'2.Regulatory'!L10,"") -> 1 | P15: =IF('2.Regulatory'!M10<>"",'2.Regulatory'!M10,"") -> 1 | Q15: =IF('2.Regulatory'!N10<>"",'2.Regulatory'!N10,"") -> 1 | R15: =IF('2.Regulatory'!O10<>"",'2.Regulatory'!O10,"") -> 1 | S15: =IF('2.Regulatory'!P10<>"",'2.Regulatory'!P10,"") -> 1 | ... W15: =IF('2.Regulatory'!T10<>"",'2.Regulatory'!T10,"") -> 1
K16: Actual | L16: =IF('2.Regulatory'!I11<>"",'2.Regulatory'!I11,"") -> 1 | M16: =IF('2.Regulatory'!J11<>"",'2.Regulatory'!J11,"") -> 1 | N16: =IF('2.Regulatory'!K11<>"",'2.Regulatory'!K11,"") -> 1 | O16: =IF('2.Regulatory'!L11<>"",'2.Regulatory'!L11,"") -> 0.91666667 | P16: =IF('2.Regulatory'!M11<>"",'2.Regulatory'!M11,"") -> 1 | Q16: =IF('2.Regulatory'!N11<>"",'2.Regulatory'!N11,"") -> 1 | R16: =IF('2.Regulatory'!O11<>"",'2.Regulatory'!O11,"") -> 1 | S16: =IF('2.Regulatory'!P11<>"",'2.Regulatory'!P11,"") -> 1 | ... W16: =IF('2.Regulatory'!T11<>"",'2.Regulatory'!T11,"")
C17: =IF(#REF!<>"",#REF!,"") -> #REF! | D17: Vinayak P | E17: =IF(#REF!<>"",#REF!,"") -> #REF! | F17: =IF(#REF!<>"",#REF!,"") -> #REF! | G17: =IF(#REF!<>"",#REF!,"") -> #REF! | H17: =IF(#REF!<>"",#REF!,"") -> #REF! | I17: =IF(#REF!<>"",#REF!,"") -> #REF! | J17: =IF(#REF!<>"",#REF!,"") -> #REF! | K17: Target | L17: =IF(#REF!<>"",#REF!,"") -> #REF! | M17: =IF(#REF!<>"",#REF!,"") -> #REF! | N17: =IF(#REF!<>"",#REF!,"") -> #REF! | O17: =IF(#REF!<>"",#REF!,"") -> #REF! | P17: =IF(#REF!<>"",#REF!,"") -> #REF! | Q17: =IF(#REF!<>"",#REF!,"") -> #REF! | R17: =IF(#REF!<>"",#REF!,"") -> #REF! | S17: =IF(#REF!<>"",#REF!,"") -> #REF! | ... W17: =IF(#REF!<>"",#REF!,"") -> #REF!
K18: Actual | L18: =IF(#REF!<>"",#REF!,"") -> #REF! | M18: =IF(#REF!<>"",#REF!,"") -> #REF! | N18: =IF(#REF!<>"",#REF!,"") -> #REF! | O18: =IF(#REF!<>"",#REF!,"") -> #REF! | P18: =IF(#REF!<>"",#REF!,"") -> #REF! | Q18: =IF(#REF!<>"",#REF!,"") -> #REF! | R18: =IF(#REF!<>"",#REF!,"") -> #REF! | S18: =IF(#REF!<>"",#REF!,"") -> #REF! | ... W18: =IF(#REF!<>"",#REF!,"") -> #REF!
C19: =IF(#REF!<>"",#REF!,"") -> #REF! | D19: Vinayak P | E19: =IF(#REF!<>"",#REF!,"") -> #REF! | F19: =IF(#REF!<>"",#REF!,"") -> #REF! | G19: =IF(#REF!<>"",#REF!,"") -> #REF! | H19: =IF(#REF!<>"",#REF!,"") -> #REF! | I19: =IF(#REF!<>"",#REF!,"") -> #REF! | J19: =IF(#REF!<>"",#REF!,"") -> #REF! | K19: Target | L19: =IF(#REF!<>"",#REF!,"") -> #REF! | M19: =IF(#REF!<>"",#REF!,"") -> #REF! | N19: =IF(#REF!<>"",#REF!,"") -> #REF! | O19: =IF(#REF!<>"",#REF!,"") -> #REF! | P19: =IF(#REF!<>"",#REF!,"") -> #REF! | Q19: =IF(#REF!<>"",#REF!,"") -> #REF! | R19: =IF(#REF!<>"",#REF!,"") -> #REF! | S19: =IF(#REF!<>"",#REF!,"") -> #REF! | ... W19: =IF(#REF!<>"",#REF!,"") -> #REF!
K20: Actual | L20: =IF(#REF!<>"",#REF!,"") -> #REF! | M20: =IF(#REF!<>"",#REF!,"") -> #REF! | N20: =IF(#REF!<>"",#REF!,"") -> #REF! | O20: =IF(#REF!<>"",#REF!,"") -> #REF! | P20: =IF(#REF!<>"",#REF!,"") -> #REF! | Q20: =IF(#REF!<>"",#REF!,"") -> #REF! | R20: =IF(#REF!<>"",#REF!,"") -> #REF! | S20: =IF(#REF!<>"",#REF!,"") -> #REF! | ... W20: =IF(#REF!<>"",#REF!,"") -> #REF!
C21: =IF(#REF!<>"",#REF!,"") -> #REF! | D21: Vinayak P | E21: =IF(#REF!<>"",#REF!,"") -> #REF! | F21: =IF(#REF!<>"",#REF!,"") -> #REF! | G21: =IF(#REF!<>"",#REF!,"") -> #REF! | H21: =IF(#REF!<>"",#REF!,"") -> #REF! | I21: =IF(#REF!<>"",#REF!,"") -> #REF! | J21: =IF(#REF!<>"",#REF!,"") -> #REF! | K21: Target | L21: =IF(#REF!<>"",#REF!,"") -> #REF! | M21: =IF(#REF!<>"",#REF!,"") -> #REF! | N21: =IF(#REF!<>"",#REF!,"") -> #REF! | O21: =IF(#REF!<>"",#REF!,"") -> #REF! | P21: =IF(#REF!<>"",#REF!,"") -> #REF! | Q21: =IF(#REF!<>"",#REF!,"") -> #REF! | R21: =IF(#REF!<>"",#REF!,"") -> #REF! | S21: =IF(#REF!<>"",#REF!,"") -> #REF! | ... W21: =IF(#REF!<>"",#REF!,"") -> #REF!
K22: Actual | L22: =IF(#REF!<>"",#REF!,"") -> #REF! | M22: =IF(#REF!<>"",#REF!,"") -> #REF! | N22: =IF(#REF!<>"",#REF!,"") -> #REF! | O22: =IF(#REF!<>"",#REF!,"") -> #REF! | P22: =IF(#REF!<>"",#REF!,"") -> #REF! | Q22: =IF(#REF!<>"",#REF!,"") -> #REF! | R22: =IF(#REF!<>"",#REF!,"") -> #REF! | S22: =IF(#REF!<>"",#REF!,"") -> #REF! | ... W22: =IF(#REF!<>"",#REF!,"") -> #REF!
A23: 2. Commercial Excellence
C31: =IF('9.NAR '!A8<>"",'9.NAR '!A8,"") -> Order Intake | D31: Mark L | E31: =IF('9.NAR '!B8<>"",'9.NAR '!B8,"") -> Financial OIT vs AOP | F31: =IF('9.NAR '!C8<>"",'9.NAR '!C8,"") -> > | G31: =IF('9.NAR '!D8<>"",'9.NAR '!D8,"") -> €40 | H31: =IF('9.NAR '!E8<>"",'9.NAR '!E8,"") -> Mn | I31: =IF('9.NAR '!F8<>"",'9.NAR '!F8,"") -> Higher the better | J31: =IF('9.NAR '!G8<>"",'9.NAR '!G8,"") -> Monthly | K31: Target | L31: =IF('9.NAR '!I8<>"",'9.NAR '!I8,"") -> 2.4 | M31: =IF('9.NAR '!J8<>"",'9.NAR '!J8,"") -> 2.4 | N31: =IF('9.NAR '!K8<>"",'9.NAR '!K8,"") -> 3.2 | O31: =IF('9.NAR '!L8<>"",'9.NAR '!L8,"") -> 2.1 | P31: =IF('9.NAR '!M8<>"",'9.NAR '!M8,"") -> 2.1 | Q31: =IF('9.NAR '!N8<>"",'9.NAR '!N8,"") -> 4.8 | R31: =IF('9.NAR '!O8<>"",'9.NAR '!O8,"") -> 2.8 | S31: =IF('9.NAR '!P8<>"",'9.NAR '!P8,"") -> 2.8 | ... W31: =IF('9.NAR '!T8<>"",'9.NAR '!T8,"") -> 4.2
K32: Actual | L32: =IF('9.NAR '!I9<>"",'9.NAR '!I9,"") -> 2.1 | M32: =IF('9.NAR '!J9<>"",'9.NAR '!J9,"") -> 2.1 | N32: =IF('9.NAR '!K9<>"",'9.NAR '!K9,"") -> 3.1 | O32: =IF('9.NAR '!L9<>"",'9.NAR '!L9,"") -> 4.1 | P32: =IF('9.NAR '!M9<>"",'9.NAR '!M9,"") -> 2.6 | Q32: =IF('9.NAR '!N9<>"",'9.NAR '!N9,"") -> 3.2 | R32: =IF('9.NAR '!O9<>"",'9.NAR '!O9,"") -> 0.8 | S32: =IF('9.NAR '!P9<>"",'9.NAR '!P9,"") | ... W32: =IF('9.NAR '!T9<>"",'9.NAR '!T9,"")
C33: =IF('9.NAR '!A10<>"",'9.NAR '!A10,"") -> POS Attachment Rate | D33: Mark L | E33: =IF('9.NAR '!B10<>"",'9.NAR '!B10,"") -> PoS Attachement | F33: =IF('9.NAR '!C10<>"",'9.NAR '!C10,"") -> >= | G33: =IF('9.NAR '!D10<>"",'9.NAR '!D10,"") -> % | H33: =IF('9.NAR '!E10<>"",'9.NAR '!E10,"") -> % | I33: =IF('9.NAR '!F10<>"",'9.NAR '!F10,"") -> Higher the better | J33: =IF('9.NAR '!G10<>"",'9.NAR '!G10,"") -> Monthly | K33: Target | L33: =IF('9.NAR '!I10<>"",'9.NAR '!I10,"") -> 40 | M33: =IF('9.NAR '!J10<>"",'9.NAR '!J10,"") -> 40 | N33: =IF('9.NAR '!K10<>"",'9.NAR '!K10,"") -> 40 | O33: =IF('9.NAR '!L10<>"",'9.NAR '!L10,"") -> 40 | P33: =IF('9.NAR '!M10<>"",'9.NAR '!M10,"") -> 40 | Q33: =IF('9.NAR '!N10<>"",'9.NAR '!N10,"") -> 40 | R33: =IF('9.NAR '!O10<>"",'9.NAR '!O10,"") -> 40 | S33: =IF('9.NAR '!P10<>"",'9.NAR '!P10,"") -> 40 | ... W33: =IF('9.NAR '!T10<>"",'9.NAR '!T10,"") -> 40
K34: Actual | L34: =IF('9.NAR '!I11<>"",'9.NAR '!I11,"") -> 60 | M34: =IF('9.NAR '!J11<>"",'9.NAR '!J11,"") -> 20 | N34: =IF('9.NAR '!K11<>"",'9.NAR '!K11,"") -> 21 | O34: =IF('9.NAR '!L11<>"",'9.NAR '!L11,"") -> 68 | P34: =IF('9.NAR '!M11<>"",'9.NAR '!M11,"") -> 38 | Q34: =IF('9.NAR '!N11<>"",'9.NAR '!N11,"") | R34: =IF('9.NAR '!O11<>"",'9.NAR '!O11,"") | S34: =IF('9.NAR '!P11<>"",'9.NAR '!P11,"") | ... W34: =IF('9.NAR '!T11<>"",'9.NAR '!T11,"")
C35: =IF('10.EUROPE '!A6<>"",'10.EUROPE '!A6,"") -> Market Share % | D35: Silvia M | E35: =IF('10.EUROPE '!B6<>"",'10.EUROPE '!B6,"") -> Q4 '26 MAT Market Share % | F35: =IF('10.EUROPE '!C6<>"",'10.EUROPE '!C6,"") -> = | G35: =IF('10.EUROPE '!D6<>"",'10.EUROPE '!D6,"") -> 0.165 | H35: =IF('10.EUROPE '!E6<>"",'10.EUROPE '!E6,"") -> % | I35: =IF('10.EUROPE '!F6<>"",'10.EUROPE '!F6,"") -> Higher the better | J35: =IF('10.EUROPE '!G6<>"",'10.EUROPE '!G6,"") -> Quarterly | K35: Target | L35: =IF('10.EUROPE '!I6<>"",'10.EUROPE '!I6,"") | M35: =IF('10.EUROPE '!J6<>"",'10.EUROPE '!J6,"") | N35: =IF('10.EUROPE '!K6<>"",'10.EUROPE '!K6,"") | O35: =IF('10.EUROPE '!L6<>"",'10.EUROPE '!L6,"") | P35: =IF('10.EUROPE '!M6<>"",'10.EUROPE '!M6,"") | Q35: =IF('10.EUROPE '!N6<>"",'10.EUROPE '!N6,"") | R35: =IF('10.EUROPE '!O6<>"",'10.EUROPE '!O6,"") | S35: =IF('10.EUROPE '!P6<>"",'10.EUROPE '!P6,"") | ... W35: =IF('10.EUROPE '!T6<>"",'10.EUROPE '!T6,"") -> 0.165
K36: Actual | L36: =IF('10.EUROPE '!I7<>"",'10.EUROPE '!I7,"") | M36: =IF('10.EUROPE '!J7<>"",'10.EUROPE '!J7,"") | N36: =IF('10.EUROPE '!K7<>"",'10.EUROPE '!K7,"") -> 0.157 | O36: =IF('10.EUROPE '!L7<>"",'10.EUROPE '!L7,"") | P36: =IF('10.EUROPE '!M7<>"",'10.EUROPE '!M7,"") -> 0.145 | Q36: =IF('10.EUROPE '!N7<>"",'10.EUROPE '!N7,"") | R36: =IF('10.EUROPE '!O7<>"",'10.EUROPE '!O7,"") | S36: =IF('10.EUROPE '!P7<>"",'10.EUROPE '!P7,"") | ... W36: =IF('10.EUROPE '!T7<>"",'10.EUROPE '!T7,"")
C37: =IF('10.EUROPE '!A8<>"",'10.EUROPE '!A8,"") -> Order Intake EQ | D37: Silvia M | E37: =IF('10.EUROPE '!B8<>"",'10.EUROPE '!B8,"") -> 2026 FY Order Intake EQ | F37: =IF('10.EUROPE '!C8<>"",'10.EUROPE '!C8,"") -> = | G37: =IF('10.EUROPE '!D8<>"",'10.EUROPE '!D8,"") -> 42 | H37: =IF('10.EUROPE '!E8<>"",'10.EUROPE '!E8,"") -> Mn | I37: =IF('10.EUROPE '!F8<>"",'10.EUROPE '!F8,"") -> Higher the better | J37: =IF('10.EUROPE '!G8<>"",'10.EUROPE '!G8,"") -> Monthly | K37: Target | L37: =IF('10.EUROPE '!I8<>"",'10.EUROPE '!I8,"") -> 3 | M37: =IF('10.EUROPE '!J8<>"",'10.EUROPE '!J8,"") -> 1.6 | N37: =IF('10.EUROPE '!K8<>"",'10.EUROPE '!K8,"") -> 3.9 | O37: =IF('10.EUROPE '!L8<>"",'10.EUROPE '!L8,"") -> 3.1 | P37: =IF('10.EUROPE '!M8<>"",'10.EUROPE '!M8,"") -> 2.1 | Q37: =IF('10.EUROPE '!N8<>"",'10.EUROPE '!N8,"") -> 4.4 | R37: =IF('10.EUROPE '!O8<>"",'10.EUROPE '!O8,"") -> 2.9 | S37: =IF('10.EUROPE '!P8<>"",'10.EUROPE '!P8,"") -> 3 | ... W37: =IF('10.EUROPE '!T8<>"",'10.EUROPE '!T8,"") -> 7.1
K38: Actual | L38: =IF('10.EUROPE '!I9<>"",'10.EUROPE '!I9,"") -> 1 | M38: =IF('10.EUROPE '!J9<>"",'10.EUROPE '!J9,"") -> 2.9 | N38: =IF('10.EUROPE '!K9<>"",'10.EUROPE '!K9,"") -> 5.4 | O38: =IF('10.EUROPE '!L9<>"",'10.EUROPE '!L9,"") -> 1.9 | P38: =IF('10.EUROPE '!M9<>"",'10.EUROPE '!M9,"") -> 1.7 | Q38: =IF('10.EUROPE '!N9<>"",'10.EUROPE '!N9,"") -> 4.4 | R38: =IF('10.EUROPE '!O9<>"",'10.EUROPE '!O9,"") -> 1.5 | S38: =IF('10.EUROPE '!P9<>"",'10.EUROPE '!P9,"") -> 1.2 | ... W38: =IF('10.EUROPE '!T9<>"",'10.EUROPE '!T9,"")
C39: =IF('10.EUROPE '!A10<>"",'10.EUROPE '!A10,"") -> Order Intake CS | D39: Silvia M | E39: =IF('10.EUROPE '!B10<>"",'10.EUROPE '!B10,"") -> 2026 FY Order Intake CS | F39: =IF('10.EUROPE '!C10<>"",'10.EUROPE '!C10,"") -> = | G39: =IF('10.EUROPE '!D10<>"",'10.EUROPE '!D10,"") -> 26.9 | H39: =IF('10.EUROPE '!E10<>"",'10.EUROPE '!E10,"") -> Mn | I39: =IF('10.EUROPE '!F10<>"",'10.EUROPE '!F10,"") -> Higher the better | J39: =IF('10.EUROPE '!G10<>"",'10.EUROPE '!G10,"") -> Monthly | K39: Target | L39: =IF('10.EUROPE '!I10<>"",'10.EUROPE '!I10,"") -> 2 | M39: =IF('10.EUROPE '!J10<>"",'10.EUROPE '!J10,"") -> 2 | N39: =IF('10.EUROPE '!K10<>"",'10.EUROPE '!K10,"") -> 3.5 | O39: =IF('10.EUROPE '!L10<>"",'10.EUROPE '!L10,"") -> 1.8 | P39: =IF('10.EUROPE '!M10<>"",'10.EUROPE '!M10,"") -> 1.8 | Q39: =IF('10.EUROPE '!N10<>"",'10.EUROPE '!N10,"") -> 1.8 | R39: =IF('10.EUROPE '!O10<>"",'10.EUROPE '!O10,"") -> 1.7 | S39: =IF('10.EUROPE '!P10<>"",'10.EUROPE '!P10,"") -> 1.3 | ... W39: =IF('10.EUROPE '!T10<>"",'10.EUROPE '!T10,"") -> 3.7
K40: Actual | L40: =IF('10.EUROPE '!I11<>"",'10.EUROPE '!I11,"") -> 2.6 | M40: =IF('10.EUROPE '!J11<>"",'10.EUROPE '!J11,"") -> 1.9 | N40: =IF('10.EUROPE '!K11<>"",'10.EUROPE '!K11,"") -> 3.6 | O40: =IF('10.EUROPE '!L11<>"",'10.EUROPE '!L11,"") -> 2.9 | P40: =IF('10.EUROPE '!M11<>"",'10.EUROPE '!M11,"") -> 1.2 | Q40: =IF('10.EUROPE '!N11<>"",'10.EUROPE '!N11,"") -> 2 | R40: =IF('10.EUROPE '!O11<>"",'10.EUROPE '!O11,"") -> 1.2 | S40: =IF('10.EUROPE '!P11<>"",'10.EUROPE '!P11,"") -> 1.3 | ... W40: =IF('10.EUROPE '!T11<>"",'10.EUROPE '!T11,"")
C41: =IF('11.GROWTH '!A6<>"",'11.GROWTH '!A6,"") -> Market Share | D41: Mahmut B | E41: =IF('11.GROWTH '!B6<>"",'11.GROWTH '!B6,"") -> MAT MS(%) | F41: =IF('11.GROWTH '!C6<>"",'11.GROWTH '!C6,"") -> = | G41: =IF('11.GROWTH '!D6<>"",'11.GROWTH '!D6,"") -> 23 | H41: =IF('11.GROWTH '!E6<>"",'11.GROWTH '!E6,"") -> % | I41: =IF('11.GROWTH '!F6<>"",'11.GROWTH '!F6,"") -> Higher the better | J41: =IF('11.GROWTH '!G6<>"",'11.GROWTH '!G6,"") -> Quarterly | K41: Target | L41: =IF('11.GROWTH '!I6<>"",'11.GROWTH '!I6,"") | M41: =IF('11.GROWTH '!J6<>"",'11.GROWTH '!J6,"") | N41: =IF('11.GROWTH '!K6<>"",'11.GROWTH '!K6,"") -> 0.2 | O41: =IF('11.GROWTH '!L6<>"",'11.GROWTH '!L6,"") | P41: =IF('11.GROWTH '!M6<>"",'11.GROWTH '!M6,"") | Q41: =IF('11.GROWTH '!N6<>"",'11.GROWTH '!N6,"") -> 0.21 | R41: =IF('11.GROWTH '!O6<>"",'11.GROWTH '!O6,"") | S41: =IF('11.GROWTH '!P6<>"",'11.GROWTH '!P6,"") | ... W41: =IF('11.GROWTH '!T6<>"",'11.GROWTH '!T6,"") -> 0.23
K42: Actual | L42: =IF('11.GROWTH '!I7<>"",'11.GROWTH '!I7,"") | M42: =IF('11.GROWTH '!J7<>"",'11.GROWTH '!J7,"") | N42: =IF('11.GROWTH '!K7<>"",'11.GROWTH '!K7,"") | O42: =IF('11.GROWTH '!L7<>"",'11.GROWTH '!L7,"") | P42: =IF('11.GROWTH '!M7<>"",'11.GROWTH '!M7,"") | Q42: =IF('11.GROWTH '!N7<>"",'11.GROWTH '!N7,"") | R42: =IF('11.GROWTH '!O7<>"",'11.GROWTH '!O7,"") | S42: =IF('11.GROWTH '!P7<>"",'11.GROWTH '!P7,"") | ... W42: =IF('11.GROWTH '!T7<>"",'11.GROWTH '!T7,"")
C43: =IF('11.GROWTH '!A8<>"",'11.GROWTH '!A8,"") -> Order Intake EQ | D43: Mahmut B | E43: =IF('11.GROWTH '!B8<>"",'11.GROWTH '!B8,"") -> AOP OIT FY | F43: =IF('11.GROWTH '!C8<>"",'11.GROWTH '!C8,"") -> = | G43: =IF('11.GROWTH '!D8<>"",'11.GROWTH '!D8,"") -> 62.9 | H43: =IF('11.GROWTH '!E8<>"",'11.GROWTH '!E8,"") -> Mn | I43: =IF('11.GROWTH '!F8<>"",'11.GROWTH '!F8,"") -> Higher the better | J43: =IF('11.GROWTH '!G8<>"",'11.GROWTH '!G8,"") -> Monthly | K43: Target | L43: =IF('11.GROWTH '!I8<>"",'11.GROWTH '!I8,"") -> 1.5 | M43: =IF('11.GROWTH '!J8<>"",'11.GROWTH '!J8,"") -> 4.5 | N43: =IF('11.GROWTH '!K8<>"",'11.GROWTH '!K8,"") -> 5.5 | O43: =IF('11.GROWTH '!L8<>"",'11.GROWTH '!L8,"") -> 4.3 | P43: =IF('11.GROWTH '!M8<>"",'11.GROWTH '!M8,"") -> 6.5 | Q43: =IF('11.GROWTH '!N8<>"",'11.GROWTH '!N8,"") -> 6.4 | R43: =IF('11.GROWTH '!O8<>"",'11.GROWTH '!O8,"") -> 3.3 | S43: =IF('11.GROWTH '!P8<>"",'11.GROWTH '!P8,"") -> 6.1 | ... W43: =IF('11.GROWTH '!T8<>"",'11.GROWTH '!T8,"") -> 6.7
K44: Actual | L44: =IF('11.GROWTH '!I9<>"",'11.GROWTH '!I9,"") -> 2.1 | M44: =IF('11.GROWTH '!J9<>"",'11.GROWTH '!J9,"") -> 3.4 | N44: =IF('11.GROWTH '!K9<>"",'11.GROWTH '!K9,"") -> 8.8 | O44: =IF('11.GROWTH '!L9<>"",'11.GROWTH '!L9,"") -> 1.2 | P44: =IF('11.GROWTH '!M9<>"",'11.GROWTH '!M9,"") | Q44: =IF('11.GROWTH '!N9<>"",'11.GROWTH '!N9,"") | R44: =IF('11.GROWTH '!O9<>"",'11.GROWTH '!O9,"") | S44: =IF('11.GROWTH '!P9<>"",'11.GROWTH '!P9,"") | ... W44: =IF('11.GROWTH '!T9<>"",'11.GROWTH '!T9,"")
C45: =IF('11.GROWTH '!A10<>"",'11.GROWTH '!A10,"") -> Order Intake CS | D45: Mahmut B | E45: =IF('11.GROWTH '!B10<>"",'11.GROWTH '!B10,"") -> AOP OIT FY | F45: =IF('11.GROWTH '!C10<>"",'11.GROWTH '!C10,"") -> = | G45: =IF('11.GROWTH '!D10<>"",'11.GROWTH '!D10,"") -> 32.2 | H45: =IF('11.GROWTH '!E10<>"",'11.GROWTH '!E10,"") -> Mn | I45: =IF('11.GROWTH '!F10<>"",'11.GROWTH '!F10,"") -> Higher the better | J45: =IF('11.GROWTH '!G10<>"",'11.GROWTH '!G10,"") -> Monthly | K45: Target | L45: =IF('11.GROWTH '!I10<>"",'11.GROWTH '!I10,"") -> 2.697 | M45: =IF('11.GROWTH '!J10<>"",'11.GROWTH '!J10,"") -> 1.91 | N45: =IF('11.GROWTH '!K10<>"",'11.GROWTH '!K10,"") -> 2.475 | O45: =IF('11.GROWTH '!L10<>"",'11.GROWTH '!L10,"") -> 2.271 | P45: =IF('11.GROWTH '!M10<>"",'11.GROWTH '!M10,"") -> 2.709 | Q45: =IF('11.GROWTH '!N10<>"",'11.GROWTH '!N10,"") -> 3.862 | R45: =IF('11.GROWTH '!O10<>"",'11.GROWTH '!O10,"") -> 2.534 | S45: =IF('11.GROWTH '!P10<>"",'11.GROWTH '!P10,"") -> 2.27 | ... W45: =IF('11.GROWTH '!T10<>"",'11.GROWTH '!T10,"") -> 4.618
K46: Actual | L46: =IF('11.GROWTH '!I11<>"",'11.GROWTH '!I11,"") -> 2 | M46: =IF('11.GROWTH '!J11<>"",'11.GROWTH '!J11,"") -> 2.2 | N46: =IF('11.GROWTH '!K11<>"",'11.GROWTH '!K11,"") -> 2.5 | O46: =IF('11.GROWTH '!L11<>"",'11.GROWTH '!L11,"") -> 2.4 | P46: =IF('11.GROWTH '!M11<>"",'11.GROWTH '!M11,"") -> 3.1 | Q46: =IF('11.GROWTH '!N11<>"",'11.GROWTH '!N11,"") -> 3.8 | R46: =IF('11.GROWTH '!O11<>"",'11.GROWTH '!O11,"") -> 2.2 | S46: =IF('11.GROWTH '!P11<>"",'11.GROWTH '!P11,"") | ... W46: =IF('11.GROWTH '!T11<>"",'11.GROWTH '!T11,"")
A47: 3. Speed up Innovation | C47: =IF('5.R&D '!A6<>"",'5.R&D '!A6,"") -> NPI On-Time (%) | D47: Shailesh A | E47: =IF('5.R&D '!B6<>"",'5.R&D '!B6,"") -> % Dhruv NPI Milestone Readiness Index (%) | F47: =IF('5.R&D '!C6<>"",'5.R&D '!C6,"") -> >= | G47: =IF('5.R&D '!D6<>"",'5.R&D '!D6,"") -> 90 | H47: =IF('5.R&D '!E6<>"",'5.R&D '!E6,"") -> % | I47: =IF('5.R&D '!F6<>"",'5.R&D '!F6,"") -> Higher the better | J47: =IF('5.R&D '!G6<>"",'5.R&D '!G6,"") -> Monthly | K47: Target | L47: =IF('5.R&D '!I6<>"",'5.R&D '!I6,"") -> 90 | M47: =IF('5.R&D '!J6<>"",'5.R&D '!J6,"") -> 90 | N47: =IF('5.R&D '!K6<>"",'5.R&D '!K6,"") -> 90 | O47: =IF('5.R&D '!L6<>"",'5.R&D '!L6,"") -> 90 | P47: =IF('5.R&D '!M6<>"",'5.R&D '!M6,"") -> 90 | Q47: =IF('5.R&D '!N6<>"",'5.R&D '!N6,"") -> 90 | R47: =IF('5.R&D '!O6<>"",'5.R&D '!O6,"") -> 90 | S47: =IF('5.R&D '!P6<>"",'5.R&D '!P6,"") -> 90 | ... W47: =IF('5.R&D '!T6<>"",'5.R&D '!T6,"") -> 90
K48: Actual | L48: =IF('5.R&D '!I7<>"",'5.R&D '!I7,"") -> 60 | M48: =IF('5.R&D '!J7<>"",'5.R&D '!J7,"") -> 64 | N48: =IF('5.R&D '!K7<>"",'5.R&D '!K7,"") -> 67 | O48: =IF('5.R&D '!L7<>"",'5.R&D '!L7,"") -> 72 | P48: =IF('5.R&D '!M7<>"",'5.R&D '!M7,"") -> 77 | Q48: =IF('5.R&D '!N7<>"",'5.R&D '!N7,"") -> 91 | R48: =IF('5.R&D '!O7<>"",'5.R&D '!O7,"") -> 93 | S48: =IF('5.R&D '!P7<>"",'5.R&D '!P7,"") -> 94 | ... W48: =IF('5.R&D '!T7<>"",'5.R&D '!T7,"")
C49: =IF('5.R&D '!A8<>"",'5.R&D '!A8,"") -> LCM Ontime (%) | D49: Shailesh A | E49: =IF('5.R&D '!B8<>"",'5.R&D '!B8,"") -> % LCM Change Requests (CRs) implemented on or before the committed implementation date (within the reporting month.) | F49: =IF('5.R&D '!C8<>"",'5.R&D '!C8,"") -> >= | G49: =IF('5.R&D '!D8<>"",'5.R&D '!D8,"") -> 85 | H49: =IF('5.R&D '!E8<>"",'5.R&D '!E8,"") -> % | I49: =IF('5.R&D '!F8<>"",'5.R&D '!F8,"") -> Higher the better | J49: =IF('5.R&D '!G8<>"",'5.R&D '!G8,"") -> Monthly | K49: Target | L49: =IF('5.R&D '!I8<>"",'5.R&D '!I8,"") -> 85 | M49: =IF('5.R&D '!J8<>"",'5.R&D '!J8,"") -> 85 | N49: =IF('5.R&D '!K8<>"",'5.R&D '!K8,"") -> 85 | O49: =IF('5.R&D '!L8<>"",'5.R&D '!L8,"") -> 85 | P49: =IF('5.R&D '!M8<>"",'5.R&D '!M8,"") -> 85 | Q49: =IF('5.R&D '!N8<>"",'5.R&D '!N8,"") -> 85 | R49: =IF('5.R&D '!O8<>"",'5.R&D '!O8,"") -> 85 | S49: =IF('5.R&D '!P8<>"",'5.R&D '!P8,"") -> 85 | ... W49: =IF('5.R&D '!T8<>"",'5.R&D '!T8,"") -> 85
K50: Actual | L50: =IF('5.R&D '!I9<>"",'5.R&D '!I9,"") -> 80 | M50: =IF('5.R&D '!J9<>"",'5.R&D '!J9,"") -> 67 | N50: =IF('5.R&D '!K9<>"",'5.R&D '!K9,"") -> 133 | O50: =IF('5.R&D '!L9<>"",'5.R&D '!L9,"") -> 50 | P50: =IF('5.R&D '!M9<>"",'5.R&D '!M9,"") -> 91 | Q50: =IF('5.R&D '!N9<>"",'5.R&D '!N9,"") -> 80 | R50: =IF('5.R&D '!O9<>"",'5.R&D '!O9,"") -> 83.3 | S50: =IF('5.R&D '!P9<>"",'5.R&D '!P9,"") -> 88 | ... W50: =IF('5.R&D '!T9<>"",'5.R&D '!T9,"")
...

Sheet MasterSheet
A1: Mastersheet
A3: Quality DMB
A4: KPI Name | B4: KPI Definition | C4: Operators | D4: Target AOP 2026 | E4: Units | F4: Metric nature | G4: Frequency | H4: Target/ Actual | I4: Jan-2026 | J4: Feb-2026 | K4: Mar-2026 | L4: Apr-2026 | M4: May-2026 | N4: Jun-2026 | O4: Jul-2026 | P4: Aug-2026 | Q4: Sep-2026 | R4: Oct-2026 | S4: Nov-2026 | T4: Dec-2026
A5: ='1.Quality'!A20 -> % CAPA implementation Tasks on time | B5: ='1.Quality'!B20 -> Number of actions completed without extension / Number of CAPA actions planned in that month as per Plan | C5: ='1.Quality'!C20 -> > | D5: ='1.Quality'!D20 -> 95 | E5: ='1.Quality'!E20 -> % | F5: ='1.Quality'!F20 -> Higher the better | G5: ='1.Quality'!G20 -> Monthly | H5: =IF('1.Quality'!H20="","",'1.Quality'!H20) -> Target | I5: =IF('1.Quality'!I20="","",'1.Quality'!I20) -> 0.95 | J5: =IF('1.Quality'!J20="","",'1.Quality'!J20) -> 0.95 | K5: =IF('1.Quality'!K20="","",'1.Quality'!K20) -> 0.95 | L5: =IF('1.Quality'!L20="","",'1.Quality'!L20) -> 0.95 | M5: =IF('1.Quality'!M20="","",'1.Quality'!M20) -> 0.95 | N5: =IF('1.Quality'!N20="","",'1.Quality'!N20) -> 0.95 | O5: =IF('1.Quality'!O20="","",'1.Quality'!O20) -> 0.95 | ... T5: =IF('1.Quality'!T20="","",'1.Quality'!T20) -> 0.95
A6: ='1.Quality'!A20 -> % CAPA implementation Tasks on time | B6: ='1.Quality'!B20 -> Number of actions completed without extension / Number of CAPA actions planned in that month as per Plan | C6: ='1.Quality'!C20 -> > | D6: ='1.Quality'!D20 -> 95 | E6: ='1.Quality'!E20 -> % | F6: ='1.Quality'!F20 -> Higher the better | G6: ='1.Quality'!G20 -> Monthly | H6: =IF('1.Quality'!H21="","",'1.Quality'!H21) -> Actual | I6: =IF('1.Quality'!I21="","",'1.Quality'!I21) -> 0.22 | J6: =IF('1.Quality'!J21="","",'1.Quality'!J21) -> 0.4 | K6: =IF('1.Quality'!K21="","",'1.Quality'!K21) -> 0.22 | L6: =IF('1.Quality'!L21="","",'1.Quality'!L21) -> 0.4 | M6: =IF('1.Quality'!M21="","",'1.Quality'!M21) -> 0.875 | N6: =IF('1.Quality'!N21="","",'1.Quality'!N21) -> 0.3 | O6: =IF('1.Quality'!O21="","",'1.Quality'!O21) -> 0.4 | ... T6: =IF('1.Quality'!T21="","",'1.Quality'!T21)
A7: ='1.Quality'!A22 -> # of C&R in pre- release(Track remaining C&R) | B7: ='1.Quality'!B22 -> # of C&Rs waiting on C&R initiation | C7: ='1.Quality'!C22 -> <= | D7: ='1.Quality'!D22 -> 10 | E7: ='1.Quality'!E22 -> No. | F7: ='1.Quality'!F22 -> Lower the better | G7: ='1.Quality'!G22 -> Monthly | H7: =IF('1.Quality'!H22="","",'1.Quality'!H22) -> Target | I7: =IF('1.Quality'!I22="","",'1.Quality'!I22) -> 6 | J7: =IF('1.Quality'!J22="","",'1.Quality'!J22) -> 5 | K7: =IF('1.Quality'!K22="","",'1.Quality'!K22) -> 5 | L7: =IF('1.Quality'!L22="","",'1.Quality'!L22) -> 4 | M7: =IF('1.Quality'!M22="","",'1.Quality'!M22) -> 4 | N7: =IF('1.Quality'!N22="","",'1.Quality'!N22) -> 4 | O7: =IF('1.Quality'!O22="","",'1.Quality'!O22) -> 4 | ... T7: =IF('1.Quality'!T22="","",'1.Quality'!T22) -> 0
A8: ='1.Quality'!A22 -> # of C&R in pre- release(Track remaining C&R) | B8: ='1.Quality'!B22 -> # of C&Rs waiting on C&R initiation | C8: ='1.Quality'!C22 -> <= | D8: ='1.Quality'!D22 -> 10 | E8: ='1.Quality'!E22 -> No. | F8: ='1.Quality'!F22 -> Lower the better | G8: ='1.Quality'!G22 -> Monthly | H8: =IF('1.Quality'!H23="","",'1.Quality'!H23) -> Actual | I8: =IF('1.Quality'!I23="","",'1.Quality'!I23) -> 6 | J8: =IF('1.Quality'!J23="","",'1.Quality'!J23) -> 5 | K8: =IF('1.Quality'!K23="","",'1.Quality'!K23) -> 5 | L8: =IF('1.Quality'!L23="","",'1.Quality'!L23) -> 4 | M8: =IF('1.Quality'!M23="","",'1.Quality'!M23) -> 4 | N8: =IF('1.Quality'!N23="","",'1.Quality'!N23) -> 4 | O8: =IF('1.Quality'!O23="","",'1.Quality'!O23) -> 4 | ... T8: =IF('1.Quality'!T23="","",'1.Quality'!T23)
A9: ='1.Quality'!#REF! -> #REF! | B9: ='1.Quality'!#REF! -> #REF! | C9: ='1.Quality'!#REF! -> #REF! | D9: ='1.Quality'!#REF! -> #REF! | E9: ='1.Quality'!#REF! -> #REF! | F9: ='1.Quality'!#REF! -> #REF! | G9: ='1.Quality'!#REF! -> #REF! | H9: =IF('1.Quality'!#REF!="","",'1.Quality'!#REF!) -> #REF! | I9: =IF('1.Quality'!#REF!="","",'1.Quality'!#REF!) -> #REF! | J9: =IF('1.Quality'!#REF!="","",'1.Quality'!#REF!) -> #REF! | K9: =IF('1.Quality'!#REF!="","",'1.Quality'!#REF!) -> #REF! | L9: =IF('1.Quality'!#REF!="","",'1.Quality'!#REF!) -> #REF! | M9: =IF('1.Quality'!#REF!="","",'1.Quality'!#REF!) -> #REF! | N9: =IF('1.Quality'!#REF!="","",'1.Quality'!#REF!) -> #REF! | O9: =IF('1.Quality'!#REF!="","",'1.Quality'!#REF!) -> #REF! | ... T9: =IF('1.Quality'!#REF!="","",'1.Quality'!#REF!) -> #REF!
A10: ='1.Quality'!#REF! -> #REF! | B10: ='1.Quality'!#REF! -> #REF! | C10: ='1.Quality'!#REF! -> #REF! | D10: ='1.Quality'!#REF! -> #REF! | E10: ='1.Quality'!#REF! -> #REF! | F10: ='1.Quality'!#REF! -> #REF! | G10: ='1.Quality'!#REF! -> #REF! | H10: =IF('1.Quality'!#REF!="","",'1.Quality'!#REF!) -> #REF! | I10: =IF('1.Quality'!#REF!="","",'1.Quality'!#REF!) -> #REF! | J10: =IF('1.Quality'!#REF!="","",'1.Quality'!#REF!) -> #REF! | K10: =IF('1.Quality'!#REF!="","",'1.Quality'!#REF!) -> #REF! | L10: =IF('1.Quality'!#REF!="","",'1.Quality'!#REF!) -> #REF! | M10: =IF('1.Quality'!#REF!="","",'1.Quality'!#REF!) -> #REF! | N10: =IF('1.Quality'!#REF!="","",'1.Quality'!#REF!) -> #REF! | O10: =IF('1.Quality'!#REF!="","",'1.Quality'!#REF!) -> #REF! | ... T10: =IF('1.Quality'!#REF!="","",'1.Quality'!#REF!) -> #REF!
A11: ='1.Quality'!#REF! -> #REF! | B11: ='1.Quality'!#REF! -> #REF! | C11: ='1.Quality'!#REF! -> #REF! | D11: ='1.Quality'!#REF! -> #REF! | E11: ='1.Quality'!#REF! -> #REF! | F11: ='1.Quality'!#REF! -> #REF! | G11: ='1.Quality'!#REF! -> #REF! | H11: =IF('1.Quality'!#REF!="","",'1.Quality'!#REF!) -> #REF! | I11: =IF('1.Quality'!#REF!="","",'1.Quality'!#REF!) -> #REF! | J11: =IF('1.Quality'!#REF!="","",'1.Quality'!#REF!) -> #REF! | K11: =IF('1.Quality'!#REF!="","",'1.Quality'!#REF!) -> #REF! | L11: =IF('1.Quality'!#REF!="","",'1.Quality'!#REF!) -> #REF! | M11: =IF('1.Quality'!#REF!="","",'1.Quality'!#REF!) -> #REF! | N11: =IF('1.Quality'!#REF!="","",'1.Quality'!#REF!) -> #REF! | O11: =IF('1.Quality'!#REF!="","",'1.Quality'!#REF!) -> #REF! | ... T11: =IF('1.Quality'!#REF!="","",'1.Quality'!#REF!) -> #REF!
A12: ='1.Quality'!#REF! -> #REF! | B12: ='1.Quality'!#REF! -> #REF! | C12: ='1.Quality'!#REF! -> #REF! | D12: ='1.Quality'!#REF! -> #REF! | E12: ='1.Quality'!#REF! -> #REF! | F12: ='1.Quality'!#REF! -> #REF! | G12: ='1.Quality'!#REF! -> #REF! | H12: =IF('1.Quality'!#REF!="","",'1.Quality'!#REF!) -> #REF! | I12: =IF('1.Quality'!#REF!="","",'1.Quality'!#REF!) -> #REF! | J12: =IF('1.Quality'!#REF!="","",'1.Quality'!#REF!) -> #REF! | K12: =IF('1.Quality'!#REF!="","",'1.Quality'!#REF!) -> #REF! | L12: =IF('1.Quality'!#REF!="","",'1.Quality'!#REF!) -> #REF! | M12: =IF('1.Quality'!#REF!="","",'1.Quality'!#REF!) -> #REF! | N12: =IF('1.Quality'!#REF!="","",'1.Quality'!#REF!) -> #REF! | O12: =IF('1.Quality'!#REF!="","",'1.Quality'!#REF!) -> #REF! | ... T12: =IF('1.Quality'!#REF!="","",'1.Quality'!#REF!) -> #REF!
A13: ='1.Quality'!A24 -> Audit | B13: ='1.Quality'!B24 -> # Major Findings in external audits | C13: ='1.Quality'!C24 -> = | D13: ='1.Quality'!D24 -> 0 | E13: ='1.Quality'!E24 -> No. | F13: ='1.Quality'!F24 -> Lower the better | G13: ='1.Quality'!G24 -> Half yearly | H13: =IF('1.Quality'!H24="","",'1.Quality'!H24) -> Target | I13: =IF('1.Quality'!I24="","",'1.Quality'!I24) -> 0 | J13: =IF('1.Quality'!J24="","",'1.Quality'!J24) -> 0 | K13: =IF('1.Quality'!K24="","",'1.Quality'!K24) -> 0 | L13: =IF('1.Quality'!L24="","",'1.Quality'!L24) -> 0 | M13: =IF('1.Quality'!M24="","",'1.Quality'!M24) -> 0 | N13: =IF('1.Quality'!N24="","",'1.Quality'!N24) -> 0 | O13: =IF('1.Quality'!O24="","",'1.Quality'!O24) -> 0 | ... T13: =IF('1.Quality'!T24="","",'1.Quality'!T24) -> 0
A14: ='1.Quality'!A24 -> Audit | B14: ='1.Quality'!B24 -> # Major Findings in external audits | C14: ='1.Quality'!C24 -> = | D14: ='1.Quality'!D24 -> 0 | E14: ='1.Quality'!E24 -> No. | F14: ='1.Quality'!F24 -> Lower the better | G14: ='1.Quality'!G24 -> Half yearly | H14: =IF('1.Quality'!H25="","",'1.Quality'!H25) -> Actual | I14: =IF('1.Quality'!I25="","",'1.Quality'!I25) -> 0 | J14: =IF('1.Quality'!J25="","",'1.Quality'!J25) -> 0 | K14: =IF('1.Quality'!K25="","",'1.Quality'!K25) -> 0 | L14: =IF('1.Quality'!L25="","",'1.Quality'!L25) -> 0 | M14: =IF('1.Quality'!M25="","",'1.Quality'!M25) -> 0 | N14: =IF('1.Quality'!N25="","",'1.Quality'!N25) -> 0 | O14: =IF('1.Quality'!O25="","",'1.Quality'!O25) -> 0 | ... T14: =IF('1.Quality'!T25="","",'1.Quality'!T25)
A16: Regulatory
A17: KPI Name | B17: KPI Definition | C17: Operators | D17: Target AOP 2026 | E17: Units | F17: Metric nature | G17: Frequency | H17: Target/ Actual | I17: Jan-2026 | J17: Feb-2026 | K17: Mar-2026 | L17: Apr-2026 | M17: May-2026 | N17: Jun-2026 | O17: Jul-2026 | P17: Aug-2026 | Q17: Sep-2026 | R17: Oct-2026 | S17: Nov-2026 | T17: Dec-2026
A18: ='2.Regulatory'!A14 -> Country readiness | B18: ='2.Regulatory'!B14 -> (Orders impacted due to regulatory or other readiness-related blocks) *100/ Total orders planned for that month | C18: ='2.Regulatory'!C14 -> <= | D18: ='2.Regulatory'!D14 -> 0.1 | E18: ='2.Regulatory'!E14 -> % | F18: ='2.Regulatory'!F14 -> Lower the better | G18: ='2.Regulatory'!G14 -> Monthly | H18: =IF('2.Regulatory'!H14="","",'2.Regulatory'!H14) -> Target | I18: =IF('2.Regulatory'!I14="","",'2.Regulatory'!I14) -> 0.1 | J18: =IF('2.Regulatory'!J14="","",'2.Regulatory'!J14) -> 0.1 | K18: =IF('2.Regulatory'!K14="","",'2.Regulatory'!K14) -> 0.1 | L18: =IF('2.Regulatory'!L14="","",'2.Regulatory'!L14) -> 0.1 | M18: =IF('2.Regulatory'!M14="","",'2.Regulatory'!M14) -> 0.1 | N18: =IF('2.Regulatory'!N14="","",'2.Regulatory'!N14) -> 0.1 | O18: =IF('2.Regulatory'!O14="","",'2.Regulatory'!O14) -> 0.1 | ... T18: =IF('2.Regulatory'!T14="","",'2.Regulatory'!T14) -> 0.1
A19: ='2.Regulatory'!A14 -> Country readiness | B19: ='2.Regulatory'!B14 -> (Orders impacted due to regulatory or other readiness-related blocks) *100/ Total orders planned for that month | C19: ='2.Regulatory'!C14 -> <= | D19: ='2.Regulatory'!D14 -> 0.1 | E19: ='2.Regulatory'!E14 -> % | F19: ='2.Regulatory'!F14 -> Lower the better | G19: ='2.Regulatory'!G14 -> Monthly | H19: =IF('2.Regulatory'!H15="","",'2.Regulatory'!H15) -> Actual | I19: =IF('2.Regulatory'!I15="","",'2.Regulatory'!I15) -> 0 | J19: =IF('2.Regulatory'!J15="","",'2.Regulatory'!J15) -> 0.011111111 | K19: =IF('2.Regulatory'!K15="","",'2.Regulatory'!K15) -> 0 | L19: =IF('2.Regulatory'!L15="","",'2.Regulatory'!L15) -> 0 | M19: =IF('2.Regulatory'!M15="","",'2.Regulatory'!M15) -> 0 | N19: =IF('2.Regulatory'!N15="","",'2.Regulatory'!N15) -> 0 | O19: =IF('2.Regulatory'!O15="","",'2.Regulatory'!O15) -> 0 | ... T19: =IF('2.Regulatory'!T15="","",'2.Regulatory'!T15)
A20: ='2.Regulatory'!A16 -> Product Change assessment | B20: ='2.Regulatory'!B16 -> (Product change assessments completed by Regulatory within 6 weeks from the date of request) *100/ Total change assessments completion planned during that month | C20: ='2.Regulatory'!C16 -> >= | D20: ='2.Regulatory'!D16 -> 0.95 | E20: ='2.Regulatory'!E16 -> % | F20: ='2.Regulatory'!F16 -> Higher the better | G20: ='2.Regulatory'!G16 -> Monthly | H20: =IF('2.Regulatory'!H16="","",'2.Regulatory'!H16) -> Target | I20: =IF('2.Regulatory'!I16="","",'2.Regulatory'!I16) -> 0.95 | J20: =IF('2.Regulatory'!J16="","",'2.Regulatory'!J16) -> 0.95 | K20: =IF('2.Regulatory'!K16="","",'2.Regulatory'!K16) -> 0.95 | L20: =IF('2.Regulatory'!L16="","",'2.Regulatory'!L16) -> 0.95 | M20: =IF('2.Regulatory'!M16="","",'2.Regulatory'!M16) -> 0.95 | N20: =IF('2.Regulatory'!N16="","",'2.Regulatory'!N16) -> 0.95 | O20: =IF('2.Regulatory'!O16="","",'2.Regulatory'!O16) -> 0.95 | ... T20: =IF('2.Regulatory'!T16="","",'2.Regulatory'!T16) -> 0.95
A21: ='2.Regulatory'!A16 -> Product Change assessment | B21: ='2.Regulatory'!B16 -> (Product change assessments completed by Regulatory within 6 weeks from the date of request) *100/ Total change assessments completion planned during that month | C21: ='2.Regulatory'!C16 -> >= | D21: ='2.Regulatory'!D16 -> 0.95 | E21: ='2.Regulatory'!E16 -> % | F21: ='2.Regulatory'!F16 -> Higher the better | G21: ='2.Regulatory'!G16 -> Monthly | H21: =IF('2.Regulatory'!H17="","",'2.Regulatory'!H17) -> Actual | I21: =IF('2.Regulatory'!I17="","",'2.Regulatory'!I17) -> 1 | J21: =IF('2.Regulatory'!J17="","",'2.Regulatory'!J17) -> 0.5 | K21: =IF('2.Regulatory'!K17="","",'2.Regulatory'!K17) -> 1 | L21: =IF('2.Regulatory'!L17="","",'2.Regulatory'!L17) -> 0 | M21: =IF('2.Regulatory'!M17="","",'2.Regulatory'!M17) -> 1 | N21: =IF('2.Regulatory'!N17="","",'2.Regulatory'!N17) -> 1 | O21: =IF('2.Regulatory'!O17="","",'2.Regulatory'!O17) -> 1 | ... T21: =IF('2.Regulatory'!T17="","",'2.Regulatory'!T17)
A22: ='2.Regulatory'!A18 -> Submission readiness | B22: ='2.Regulatory'!B18 -> (Completed regulatory submission documents) *100/ Total submission deliverables needed for each planned country submission | C22: ='2.Regulatory'!C18 -> = | D22: ='2.Regulatory'!D18 -> 1 | E22: ='2.Regulatory'!E18 -> % | F22: ='2.Regulatory'!F18 -> Higher the better | G22: ='2.Regulatory'!G18 -> Monthly | H22: =IF('2.Regulatory'!H18="","",'2.Regulatory'!H18) -> Target | I22: =IF('2.Regulatory'!I18="","",'2.Regulatory'!I18) -> 1 | J22: =IF('2.Regulatory'!J18="","",'2.Regulatory'!J18) -> 1 | K22: =IF('2.Regulatory'!K18="","",'2.Regulatory'!K18) -> 1 | L22: =IF('2.Regulatory'!L18="","",'2.Regulatory'!L18) -> 1 | M22: =IF('2.Regulatory'!M18="","",'2.Regulatory'!M18) -> 1 | N22: =IF('2.Regulatory'!N18="","",'2.Regulatory'!N18) -> 1 | O22: =IF('2.Regulatory'!O18="","",'2.Regulatory'!O18) -> 1 | ... T22: =IF('2.Regulatory'!T18="","",'2.Regulatory'!T18) -> 1
A23: ='2.Regulatory'!A18 -> Submission readiness | B23: ='2.Regulatory'!B18 -> (Completed regulatory submission documents) *100/ Total submission deliverables needed for each planned country submission | C23: ='2.Regulatory'!C18 -> = | D23: ='2.Regulatory'!D18 -> 1 | E23: ='2.Regulatory'!E18 -> % | F23: ='2.Regulatory'!F18 -> Higher the better | G23: ='2.Regulatory'!G18 -> Monthly | H23: =IF('2.Regulatory'!H19="","",'2.Regulatory'!H19) -> Actual | I23: =IF('2.Regulatory'!I19="","",'2.Regulatory'!I19) -> 1 | J23: =IF('2.Regulatory'!J19="","",'2.Regulatory'!J19) -> 1 | K23: =IF('2.Regulatory'!K19="","",'2.Regulatory'!K19) -> 1 | L23: =IF('2.Regulatory'!L19="","",'2.Regulatory'!L19) -> 0.93939394 | M23: =IF('2.Regulatory'!M19="","",'2.Regulatory'!M19) -> 1 | N23: =IF('2.Regulatory'!N19="","",'2.Regulatory'!N19) -> 1 | O23: =IF('2.Regulatory'!O19="","",'2.Regulatory'!O19) -> 1 | ... T23: =IF('2.Regulatory'!T19="","",'2.Regulatory'!T19)
A24: ='2.Regulatory'!A20 -> Quality of submission | B24: ='2.Regulatory'!B20 -> (Planned regulatory submissions accepted first-time-right) *100/ Total submission submitted in that month | C24: ='2.Regulatory'!C20 -> >= | D24: ='2.Regulatory'!D20 -> 0.95 | E24: ='2.Regulatory'!E20 -> % | F24: ='2.Regulatory'!F20 -> Higher the better | G24: ='2.Regulatory'!G20 -> Monthly | H24: =IF('2.Regulatory'!H20="","",'2.Regulatory'!H20) -> Target | I24: =IF('2.Regulatory'!I20="","",'2.Regulatory'!I20) -> 0.95 | J24: =IF('2.Regulatory'!J20="","",'2.Regulatory'!J20) -> 0.95 | K24: =IF('2.Regulatory'!K20="","",'2.Regulatory'!K20) -> 0.95 | L24: =IF('2.Regulatory'!L20="","",'2.Regulatory'!L20) -> 0.95 | M24: =IF('2.Regulatory'!M20="","",'2.Regulatory'!M20) -> 0.95 | N24: =IF('2.Regulatory'!N20="","",'2.Regulatory'!N20) -> 0.95 | O24: =IF('2.Regulatory'!O20="","",'2.Regulatory'!O20) -> 0.95 | ... T24: =IF('2.Regulatory'!T20="","",'2.Regulatory'!T20) -> 0.95
A25: ='2.Regulatory'!A20 -> Quality of submission | B25: ='2.Regulatory'!B20 -> (Planned regulatory submissions accepted first-time-right) *100/ Total submission submitted in that month | C25: ='2.Regulatory'!C20 -> >= | D25: ='2.Regulatory'!D20 -> 0.95 | E25: ='2.Regulatory'!E20 -> % | F25: ='2.Regulatory'!F20 -> Higher the better | G25: ='2.Regulatory'!G20 -> Monthly | H25: =IF('2.Regulatory'!H21="","",'2.Regulatory'!H21) -> Actual | I25: =IF('2.Regulatory'!I21="","",'2.Regulatory'!I21) -> 1 | J25: =IF('2.Regulatory'!J21="","",'2.Regulatory'!J21) -> 1 | K25: =IF('2.Regulatory'!K21="","",'2.Regulatory'!K21) -> 0.97058824 | L25: =IF('2.Regulatory'!L21="","",'2.Regulatory'!L21) -> 1 | M25: =IF('2.Regulatory'!M21="","",'2.Regulatory'!M21) -> 1 | N25: =IF('2.Regulatory'!N21="","",'2.Regulatory'!N21) -> 1 | O25: =IF('2.Regulatory'!O21="","",'2.Regulatory'!O21) -> 1 | ... T25: =IF('2.Regulatory'!T21="","",'2.Regulatory'!T21)
A27: ISC
A28: KPI Name | B28: KPI Definition | C28: Operators | D28: Target AOP 2026 | E28: Units | F28: Metric nature | G28: Frequency | H28: Target/ Actual | I28: Jan-2026 | J28: Feb-2026 | K28: Mar-2026 | L28: Apr-2026 | M28: May-2026 | N28: Jun-2026 | O28: Jul-2026 | P28: Aug-2026 | Q28: Sep-2026 | R28: Oct-2026 | S28: Nov-2026 | T28: Dec-2026
A29: ='3.ISC '!A14 -> Ontime supply | B29: ='3.ISC '!B14 -> FSD adherance | C29: ='3.ISC '!C14 -> > | D29: ='3.ISC '!D14 -> 0.9 | E29: ='3.ISC '!E14 -> % | F29: ='3.ISC '!F14 -> Higher the better | G29: ='3.ISC '!G14 -> Monthly | H29: =IF('3.ISC '!H14="","",'3.ISC '!H14) -> Target | I29: =IF('3.ISC '!I14="","",'3.ISC '!I14) -> 0.9 | J29: =IF('3.ISC '!J14="","",'3.ISC '!J14) -> 0.9 | K29: =IF('3.ISC '!K14="","",'3.ISC '!K14) -> 0.9 | L29: =IF('3.ISC '!L14="","",'3.ISC '!L14) -> 0.9 | M29: =IF('3.ISC '!M14="","",'3.ISC '!M14) -> 0.9 | N29: =IF('3.ISC '!N14="","",'3.ISC '!N14) -> 0.9 | O29: =IF('3.ISC '!O14="","",'3.ISC '!O14) -> 0.9 | ... T29: =IF('3.ISC '!T14="","",'3.ISC '!T14) -> 0.9
A30: ='3.ISC '!A14 -> Ontime supply | B30: ='3.ISC '!B14 -> FSD adherance | C30: ='3.ISC '!C14 -> > | D30: ='3.ISC '!D14 -> 0.9 | E30: ='3.ISC '!E14 -> % | F30: ='3.ISC '!F14 -> Higher the better | G30: ='3.ISC '!G14 -> Monthly | H30: =IF('3.ISC '!H15="","",'3.ISC '!H15) -> Actual | I30: =IF('3.ISC '!I15="","",'3.ISC '!I15) -> 0.91 | J30: =IF('3.ISC '!J15="","",'3.ISC '!J15) -> 0.96 | K30: =IF('3.ISC '!K15="","",'3.ISC '!K15) -> 0.66 | L30: =IF('3.ISC '!L15="","",'3.ISC '!L15) -> 0.73 | M30: =IF('3.ISC '!M15="","",'3.ISC '!M15) -> 0.71 | N30: =IF('3.ISC '!N15="","",'3.ISC '!N15) -> 0.95 | O30: =IF('3.ISC '!O15="","",'3.ISC '!O15) -> 0.92 | ... T30: =IF('3.ISC '!T15="","",'3.ISC '!T15)
A31: ='3.ISC '!A16 -> Production units | B31: ='3.ISC '!B16 -> Production number | C31: ='3.ISC '!C16 -> > | D31: ='3.ISC '!D16 -> 1332/1400 | E31: ='3.ISC '!E16 -> No. | F31: ='3.ISC '!F16 -> Higher the better | G31: ='3.ISC '!G16 -> Monthly | H31: =IF('3.ISC '!H16="","",'3.ISC '!H16) -> Target | I31: =IF('3.ISC '!I16="","",'3.ISC '!I16) | J31: =IF('3.ISC '!J16="","",'3.ISC '!J16) -> 118 | K31: =IF('3.ISC '!K16="","",'3.ISC '!K16) -> 124 | L31: =IF('3.ISC '!L16="","",'3.ISC '!L16) -> 129 | M31: =IF('3.ISC '!M16="","",'3.ISC '!M16) -> 132 | N31: =IF('3.ISC '!N16="","",'3.ISC '!N16) -> 130 | O31: =IF('3.ISC '!O16="","",'3.ISC '!O16) -> 125 | ... T31: =IF('3.ISC '!T16="","",'3.ISC '!T16) -> 79
A32: ='3.ISC '!A16 -> Production units | B32: ='3.ISC '!B16 -> Production number | C32: ='3.ISC '!C16 -> > | D32: ='3.ISC '!D16 -> 1332/1400 | E32: ='3.ISC '!E16 -> No. | F32: ='3.ISC '!F16 -> Higher the better | G32: ='3.ISC '!G16 -> Monthly | H32: =IF('3.ISC '!H17="","",'3.ISC '!H17) -> Actual | I32: =IF('3.ISC '!I17="","",'3.ISC '!I17) -> 113 | J32: =IF('3.ISC '!J17="","",'3.ISC '!J17) -> 119 | K32: =IF('3.ISC '!K17="","",'3.ISC '!K17) -> 111 | L32: =IF('3.ISC '!L17="","",'3.ISC '!L17) -> 89 | M32: =IF('3.ISC '!M17="","",'3.ISC '!M17) -> 113 | N32: =IF('3.ISC '!N17="","",'3.ISC '!N17) -> 109 | O32: =IF('3.ISC '!O17="","",'3.ISC '!O17) -> 116 | ... T32: =IF('3.ISC '!T17="","",'3.ISC '!T17)
A33: ='3.ISC '!A18 -> CTB (12 weeks) | B33: ='3.ISC '!B18 -> Clear to build material avaialbility | C33: ='3.ISC '!C18 -> > | D33: ='3.ISC '!D18 -> 0.9 | E33: ='3.ISC '!E18 -> % | F33: ='3.ISC '!F18 -> Higher the better | G33: ='3.ISC '!G18 -> Monthly | H33: =IF('3.ISC '!H18="","",'3.ISC '!H18) -> Target | I33: =IF('3.ISC '!I18="","",'3.ISC '!I18) -> 0.85 | J33: =IF('3.ISC '!J18="","",'3.ISC '!J18) -> 0.87 | K33: =IF('3.ISC '!K18="","",'3.ISC '!K18) -> 0.9 | L33: =IF('3.ISC '!L18="","",'3.ISC '!L18) -> 0.9 | M33: =IF('3.ISC '!M18="","",'3.ISC '!M18) -> 0.9 | N33: =IF('3.ISC '!N18="","",'3.ISC '!N18) -> 0.9 | O33: =IF('3.ISC '!O18="","",'3.ISC '!O18) -> 0.9 | ... T33: =IF('3.ISC '!T18="","",'3.ISC '!T18) -> 0.92
A34: ='3.ISC '!A18 -> CTB (12 weeks) | B34: ='3.ISC '!B18 -> Clear to build material avaialbility | C34: ='3.ISC '!C18 -> > | D34: ='3.ISC '!D18 -> 0.9 | E34: ='3.ISC '!E18 -> % | F34: ='3.ISC '!F18 -> Higher the better | G34: ='3.ISC '!G18 -> Monthly | H34: =IF('3.ISC '!H19="","",'3.ISC '!H19) -> Actual | I34: =IF('3.ISC '!I19="","",'3.ISC '!I19) -> 0.93 | J34: =IF('3.ISC '!J19="","",'3.ISC '!J19) -> 0.89 | K34: =IF('3.ISC '!K19="","",'3.ISC '!K19) -> 0.88 | L34: =IF('3.ISC '!L19="","",'3.ISC '!L19) -> 0.84 | M34: =IF('3.ISC '!M19="","",'3.ISC '!M19) -> 0.93 | N34: =IF('3.ISC '!N19="","",'3.ISC '!N19) -> 0.93 | O34: =IF('3.ISC '!O19="","",'3.ISC '!O19) -> 0.92 | ... T34: =IF('3.ISC '!T19="","",'3.ISC '!T19)
A35: ='3.ISC '!A20 -> OOH % | B35: ='3.ISC '!B20 -> OOH % for revnue in the Qtr | C35: ='3.ISC '!C20 -> > | D35: ='3.ISC '!D20 -> % | E35: ='3.ISC '!E20 -> % | F35: ='3.ISC '!F20 -> Higher the better | G35: ='3.ISC '!G20 -> Monthly | H35: =IF('3.ISC '!H20="","",'3.ISC '!H20) -> Target | I35: =IF('3.ISC '!I20="","",'3.ISC '!I20) -> 0.8 | J35: =IF('3.ISC '!J20="","",'3.ISC '!J20) -> 0.9 | K35: =IF('3.ISC '!K20="","",'3.ISC '!K20) -> 0.95 | L35: =IF('3.ISC '!L20="","",'3.ISC '!L20) -> 0.8 | M35: =IF('3.ISC '!M20="","",'3.ISC '!M20) -> 0.9 | N35: =IF('3.ISC '!N20="","",'3.ISC '!N20) -> 0.95 | O35: =IF('3.ISC '!O20="","",'3.ISC '!O20) -> 0.8 | ... T35: =IF('3.ISC '!T20="","",'3.ISC '!T20)
A36: ='3.ISC '!A20 -> OOH % | B36: ='3.ISC '!B20 -> OOH % for revnue in the Qtr | C36: ='3.ISC '!C20 -> > | D36: ='3.ISC '!D20 -> % | E36: ='3.ISC '!E20 -> % | F36: ='3.ISC '!F20 -> Higher the better | G36: ='3.ISC '!G20 -> Monthly | H36: =IF('3.ISC '!H21="","",'3.ISC '!H21) -> Actual | I36: =IF('3.ISC '!I21="","",'3.ISC '!I21) -> 0.8 | J36: =IF('3.ISC '!J21="","",'3.ISC '!J21) -> 0.9 | K36: =IF('3.ISC '!K21="","",'3.ISC '!K21) -> 1.02 | L36: =IF('3.ISC '!L21="","",'3.ISC '!L21) -> 0.6 | M36: =IF('3.ISC '!M21="","",'3.ISC '!M21) -> 0.72 | N36: =IF('3.ISC '!N21="","",'3.ISC '!N21) -> 0.81 | O36: =IF('3.ISC '!O21="","",'3.ISC '!O21) -> 0.56 | ... T36: =IF('3.ISC '!T21="","",'3.ISC '!T21)
A37: ='3.ISC '!A22 -> Market Inventory | B37: ='3.ISC '!B22 -> Market inventory | C37: ='3.ISC '!C22 -> < | D37: ='3.ISC '!D22 -> 10 % reduction | E37: ='3.ISC '!E22 -> Mn | F37: ='3.ISC '!F22 -> Lower the better | G37: ='3.ISC '!G22 -> Monthly | H37: =IF('3.ISC '!H22="","",'3.ISC '!H22) -> Target | I37: =IF('3.ISC '!I22="","",'3.ISC '!I22) -> 11.540479 | J37: =IF('3.ISC '!J22="","",'3.ISC '!J22) -> 13.985593 | K37: =IF('3.ISC '!K22="","",'3.ISC '!K22) -> 14.900208 | L37: =IF('3.ISC '!L22="","",'3.ISC '!L22) -> 15.546561 | M37: =IF('3.ISC '!M22="","",'3.ISC '!M22) -> 12.923735 | N37: =IF('3.ISC '!N22="","",'3.ISC '!N22) -> 13.018238 | O37: =IF('3.ISC '!O22="","",'3.ISC '!O22) -> 11.345502 | ... T37: =IF('3.ISC '!T22="","",'3.ISC '!T22) -> 9.5717963
A38: ='3.ISC '!A22 -> Market Inventory | B38: ='3.ISC '!B22 -> Market inventory | C38: ='3.ISC '!C22 -> < | D38: ='3.ISC '!D22 -> 10 % reduction | E38: ='3.ISC '!E22 -> Mn | F38: ='3.ISC '!F22 -> Lower the better | G38: ='3.ISC '!G22 -> Monthly | H38: =IF('3.ISC '!H23="","",'3.ISC '!H23) -> Actual | I38: =IF('3.ISC '!I23="","",'3.ISC '!I23) -> 17.3 | J38: =IF('3.ISC '!J23="","",'3.ISC '!J23) -> 21.89 | K38: =IF('3.ISC '!K23="","",'3.ISC '!K23) -> 21.44 | L38: =IF('3.ISC '!L23="","",'3.ISC '!L23) -> 24.02 | M38: =IF('3.ISC '!M23="","",'3.ISC '!M23) -> 24.1 | N38: =IF('3.ISC '!N23="","",'3.ISC '!N23) -> 22.5 | O38: =IF('3.ISC '!O23="","",'3.ISC '!O23) -> 23 | ... T38: =IF('3.ISC '!T23="","",'3.ISC '!T23)
A39: ='3.ISC '!A24 -> CDD push out / month | B39: ='3.ISC '!B24 -> CDD move out during to execution | C39: ='3.ISC '!C24 -> <= | D39: ='3.ISC '!D24 -> 15 | E39: ='3.ISC '!E24 -> No. | F39: ='3.ISC '!F24 -> Lower the better | G39: ='3.ISC '!G24 -> Monthly | H39: =IF('3.ISC '!H24="","",'3.ISC '!H24) -> Target | I39: =IF('3.ISC '!I24="","",'3.ISC '!I24) -> 15 | J39: =IF('3.ISC '!J24="","",'3.ISC '!J24) -> 15 | K39: =IF('3.ISC '!K24="","",'3.ISC '!K24) -> 15 | L39: =IF('3.ISC '!L24="","",'3.ISC '!L24) -> 15 | M39: =IF('3.ISC '!M24="","",'3.ISC '!M24) -> 15 | N39: =IF('3.ISC '!N24="","",'3.ISC '!N24) -> 15 | O39: =IF('3.ISC '!O24="","",'3.ISC '!O24) -> 15 | ... T39: =IF('3.ISC '!T24="","",'3.ISC '!T24) -> 15
A40: ='3.ISC '!A24 -> CDD push out / month | B40: ='3.ISC '!B24 -> CDD move out during to execution | C40: ='3.ISC '!C24 -> <= | D40: ='3.ISC '!D24 -> 15 | E40: ='3.ISC '!E24 -> No. | F40: ='3.ISC '!F24 -> Lower the better | G40: ='3.ISC '!G24 -> Monthly | H40: =IF('3.ISC '!H25="","",'3.ISC '!H25) -> Actual | I40: =IF('3.ISC '!I25="","",'3.ISC '!I25) -> 7 | J40: =IF('3.ISC '!J25="","",'3.ISC '!J25) -> 8 | K40: =IF('3.ISC '!K25="","",'3.ISC '!K25) -> 28 | L40: =IF('3.ISC '!L25="","",'3.ISC '!L25) -> 16 | M40: =IF('3.ISC '!M25="","",'3.ISC '!M25) -> 20 | N40: =IF('3.ISC '!N25="","",'3.ISC '!N25) -> 9 | O40: =IF('3.ISC '!O25="","",'3.ISC '!O25) -> 13 | ... T40: =IF('3.ISC '!T25="","",'3.ISC '!T25)
A42: Supplier Quality
A43: KPI Name | B43: KPI Definition | C43: Operators | D43: Target AOP 2026 | E43: Units | F43: Metric nature | G43: Frequency | H43: Target/ Actual | I43: Jan-2026 | J43: Feb-2026 | K43: Mar-2026 | L43: Apr-2026 | M43: May-2026 | N43: Jun-2026 | O43: Jul-2026 | P43: Aug-2026 | Q43: Sep-2026 | R43: Oct-2026 | S43: Nov-2026 | T43: Dec-2026
A44: ='3.ISC '!#REF! -> #REF! | B44: ='3.ISC '!#REF! -> #REF! | C44: ='3.ISC '!#REF! -> #REF! | D44: ='3.ISC '!#REF! -> #REF! | E44: ='3.ISC '!#REF! -> #REF! | F44: ='3.ISC '!#REF! -> #REF! | G44: ='3.ISC '!#REF! -> #REF! | H44: =IF('3.ISC '!#REF!="","",'3.ISC '!#REF!) -> #REF! | I44: =IF('3.ISC '!#REF!="","",'3.ISC '!#REF!) -> #REF! | J44: =IF('3.ISC '!#REF!="","",'3.ISC '!#REF!) -> #REF! | K44: =IF('3.ISC '!#REF!="","",'3.ISC '!#REF!) -> #REF! | L44: =IF('3.ISC '!#REF!="","",'3.ISC '!#REF!) -> #REF! | M44: =IF('3.ISC '!#REF!="","",'3.ISC '!#REF!) -> #REF! | N44: =IF('3.ISC '!#REF!="","",'3.ISC '!#REF!) -> #REF! | O44: =IF('3.ISC '!#REF!="","",'3.ISC '!#REF!) -> #REF! | ... T44: =IF('3.ISC '!#REF!="","",'3.ISC '!#REF!) -> #REF!
...

Sheet 1.Quality
A1: Month | B1: 46023 | C1: MT Owner: | D1: Neena S | E1: MT Delegate: | W1: Actual green | X1: =IF(I21<>"",IF($F20="Higher the better",IF(I21>=I20,I21,NA()),IF(I21<=I20,I21,NA())),NA()) -> #N/A | Y1: =IF(J21<>"",IF($F20="Higher the better",IF(J21>=J20,J21,NA()),IF(J21<=J20,J21,NA())),NA()) -> #N/A | Z1: =IF(K21<>"",IF($F20="Higher the better",IF(K21>=K20,K21,NA()),IF(K21<=K20,K21,NA())),NA()) -> #N/A | AA1: =IF(L21<>"",IF($F20="Higher the better",IF(L21>=L20,L21,NA()),IF(L21<=L20,L21,NA())),NA()) -> #N/A | AB1: =IF(M21<>"",IF($F20="Higher the better",IF(M21>=M20,M21,NA()),IF(M21<=M20,M21,NA())),NA()) -> #N/A | AC1: =IF(N21<>"",IF($F20="Higher the better",IF(N21>=N20,N21,NA()),IF(N21<=N20,N21,NA())),NA()) -> #N/A | AD1: =IF(O21<>"",IF($F20="Higher the better",IF(O21>=O20,O21,NA()),IF(O21<=O20,O21,NA())),NA()) -> #N/A | AE1: =IF(P21<>"",IF($F20="Higher the better",IF(P21>=P20,P21,NA()),IF(P21<=P20,P21,NA())),NA()) -> #N/A | ... AI1: =IF(T21<>"",IF($F20="Higher the better",IF(T21>=T20,T21,NA()),IF(T21<=T20,T21,NA())),NA()) -> #N/A
W2: Actual red | X2: =IF(I21<>"",IF($F20="Higher the better",IF(I21<I20,I21,NA()),IF(I21>I20,I21,NA())),NA()) -> 0.22 | Y2: =IF(J21<>"",IF($F20="Higher the better",IF(J21<J20,J21,NA()),IF(J21>J20,J21,NA())),NA()) -> 0.4 | Z2: =IF(K21<>"",IF($F20="Higher the better",IF(K21<K20,K21,NA()),IF(K21>K20,K21,NA())),NA()) -> 0.22 | AA2: =IF(L21<>"",IF($F20="Higher the better",IF(L21<L20,L21,NA()),IF(L21>L20,L21,NA())),NA()) -> 0.4 | AB2: =IF(M21<>"",IF($F20="Higher the better",IF(M21<M20,M21,NA()),IF(M21>M20,M21,NA())),NA()) -> 0.875 | AC2: =IF(N21<>"",IF($F20="Higher the better",IF(N21<N20,N21,NA()),IF(N21>N20,N21,NA())),NA()) -> 0.3 | AD2: =IF(O21<>"",IF($F20="Higher the better",IF(O21<O20,O21,NA()),IF(O21>O20,O21,NA())),NA()) -> 0.4 | AE2: =IF(P21<>"",IF($F20="Higher the better",IF(P21<P20,P21,NA()),IF(P21>P20,P21,NA())),NA()) -> 0.83 | ... AI2: =IF(T21<>"",IF($F20="Higher the better",IF(T21<T20,T21,NA()),IF(T21>T20,T21,NA())),NA()) -> #N/A
A3: Patient Safety & Quality DMB | W3: Actual green | X3: =IF(I23<>"",IF($F22="Higher the better",IF(I23>=I22,I23,NA()),IF(I23<=I22,I23,NA())),NA()) -> 6 | Y3: =IF(J23<>"",IF($F22="Higher the better",IF(J23>=J22,J23,NA()),IF(J23<=J22,J23,NA())),NA()) -> 5 | Z3: =IF(K23<>"",IF($F22="Higher the better",IF(K23>=K22,K23,NA()),IF(K23<=K22,K23,NA())),NA()) -> 5 | AA3: =IF(L23<>"",IF($F22="Higher the better",IF(L23>=L22,L23,NA()),IF(L23<=L22,L23,NA())),NA()) -> 4 | AB3: =IF(M23<>"",IF($F22="Higher the better",IF(M23>=M22,M23,NA()),IF(M23<=M22,M23,NA())),NA()) -> 4 | AC3: =IF(N23<>"",IF($F22="Higher the better",IF(N23>=N22,N23,NA()),IF(N23<=N22,N23,NA())),NA()) -> 4 | AD3: =IF(O23<>"",IF($F22="Higher the better",IF(O23>=O22,O23,NA()),IF(O23<=O22,O23,NA())),NA()) -> 4 | AE3: =IF(P23<>"",IF($F22="Higher the better",IF(P23>=P22,P23,NA()),IF(P23<=P22,P23,NA())),NA()) -> 2 | ... AI3: =IF(T23<>"",IF($F22="Higher the better",IF(T23>=T22,T23,NA()),IF(T23<=T22,T23,NA())),NA()) -> #N/A
A4: Mandatory Outcome KPI's (1-3) | W4: Actual red | X4: {=IF(I23<>"",IF($F22="Higher the better",IF(I23<X5I22,I23,NA()),IF(I23>I22,I23,NA())),NA())} -> #N/A | Y4: =IF(J23<>"",IF($F22="Higher the better",IF(J23<J22,J23,NA()),IF(J23>J22,J23,NA())),NA()) -> #N/A | Z4: =IF(K23<>"",IF($F22="Higher the better",IF(K23<K22,K23,NA()),IF(K23>K22,K23,NA())),NA()) -> #N/A | AA4: =IF(L23<>"",IF($F22="Higher the better",IF(L23<L22,L23,NA()),IF(L23>L22,L23,NA())),NA()) -> #N/A | AB4: =IF(M23<>"",IF($F22="Higher the better",IF(M23<M22,M23,NA()),IF(M23>M22,M23,NA())),NA()) -> #N/A | AC4: =IF(N23<>"",IF($F22="Higher the better",IF(N23<N22,N23,NA()),IF(N23>N22,N23,NA())),NA()) -> #N/A | AD4: =IF(O23<>"",IF($F22="Higher the better",IF(O23<O22,O23,NA()),IF(O23>O22,O23,NA())),NA()) -> #N/A | AE4: =IF(P23<>"",IF($F22="Higher the better",IF(P23<P22,P23,NA()),IF(P23>P22,P23,NA())),NA()) -> #N/A | AF4: =IF(Q23<>"",IF($F22="Higher the better",IF(Q23<Q22,Q23,NA()),IF(Q23>Q22,Q23,NA())),NA()) -> #N/A | ... AI4: =IF(T23<>"",IF($F22="Higher the better",IF(T23<T22,T23,NA()),IF(T23>T22,T23,NA())),NA()) -> #N/A
A5: KPI Name | B5: KPI Definition | C5: Operators | D5: Target AOP 2026 | E5: Units | F5: Metric nature | G5: Frequency | H5: Target/ Actual | I5: 46023 | J5: 46054 | K5: 46082 | L5: 46113 | M5: 46143 | N5: 46174 | O5: 46204 | P5: 46235 | Q5: 46266 | R5: 46296 | S5: 46327 | T5: 46357 | W5: Actual green | X5: =IF(#REF!<>"",IF(#REF!="Higher the better",IF(#REF!>=#REF!,#REF!,NA()),IF(#REF!<=#REF!,#REF!,NA())),NA()) -> #REF! | Y5: =IF(#REF!<>"",IF(#REF!="Higher the better",IF(#REF!>=#REF!,#REF!,NA()),IF(#REF!<=#REF!,#REF!,NA())),NA()) -> #REF! | Z5: =IF(#REF!<>"",IF(#REF!="Higher the better",IF(#REF!>=#REF!,#REF!,NA()),IF(#REF!<=#REF!,#REF!,NA())),NA()) -> #REF! | AA5: =IF(#REF!<>"",IF(#REF!="Higher the better",IF(#REF!>=#REF!,#REF!,NA()),IF(#REF!<=#REF!,#REF!,NA())),NA()) -> #REF! | AB5: =IF(#REF!<>"",IF(#REF!="Higher the better",IF(#REF!>=#REF!,#REF!,NA()),IF(#REF!<=#REF!,#REF!,NA())),NA()) -> #REF! | AC5: =IF(#REF!<>"",IF(#REF!="Higher the better",IF(#REF!>=#REF!,#REF!,NA()),IF(#REF!<=#REF!,#REF!,NA())),NA()) -> #REF! | AD5: =IF(#REF!<>"",IF(#REF!="Higher the better",IF(#REF!>=#REF!,#REF!,NA()),IF(#REF!<=#REF!,#REF!,NA())),NA()) -> #REF! | AE5: =IF(#REF!<>"",IF(#REF!="Higher the better",IF(#REF!>=#REF!,#REF!,NA()),IF(#REF!<=#REF!,#REF!,NA())),NA()) -> #REF! | ... AI5: =IF(#REF!<>"",IF(#REF!="Higher the better",IF(#REF!>=#REF!,#REF!,NA()),IF(#REF!<=#REF!,#REF!,NA())),NA()) -> #REF!
A6: % CAPA Investigations Currently ≤ 90 days | B6: Timeliness of investigations | C6: >= | D6: 90 | E6: % | F6: Higher the better | G6: Monthly | H6: Target | I6: 0.9 | J6: 0.9 | K6: 0.9 | L6: 0.9 | M6: 0.9 | N6: 0.9 | O6: 0.9 | P6: 0.9 | Q6: 0.9 | R6: 0.9 | S6: 0.9 | T6: 0.9 | W6: Actual red | X6: =IF(#REF!<>"",IF(#REF!="Higher the better",IF(#REF!<#REF!,#REF!,NA()),IF(#REF!>#REF!,#REF!,NA())),NA()) -> #REF! | Y6: =IF(#REF!<>"",IF(#REF!="Higher the better",IF(#REF!<#REF!,#REF!,NA()),IF(#REF!>#REF!,#REF!,NA())),NA()) -> #REF! | Z6: =IF(#REF!<>"",IF(#REF!="Higher the better",IF(#REF!<#REF!,#REF!,NA()),IF(#REF!>#REF!,#REF!,NA())),NA()) -> #REF! | AA6: =IF(#REF!<>"",IF(#REF!="Higher the better",IF(#REF!<#REF!,#REF!,NA()),IF(#REF!>#REF!,#REF!,NA())),NA()) -> #REF! | AB6: =IF(#REF!<>"",IF(#REF!="Higher the better",IF(#REF!<#REF!,#REF!,NA()),IF(#REF!>#REF!,#REF!,NA())),NA()) -> #REF! | AC6: =IF(#REF!<>"",IF(#REF!="Higher the better",IF(#REF!<#REF!,#REF!,NA()),IF(#REF!>#REF!,#REF!,NA())),NA()) -> #REF! | AD6: =IF(#REF!<>"",IF(#REF!="Higher the better",IF(#REF!<#REF!,#REF!,NA()),IF(#REF!>#REF!,#REF!,NA())),NA()) -> #REF! | AE6: =IF(#REF!<>"",IF(#REF!="Higher the better",IF(#REF!<#REF!,#REF!,NA()),IF(#REF!>#REF!,#REF!,NA())),NA()) -> #REF! | ... AI6: =IF(#REF!<>"",IF(#REF!="Higher the better",IF(#REF!<#REF!,#REF!,NA()),IF(#REF!>#REF!,#REF!,NA())),NA()) -> #REF!
