Workbook

Sheet Mastersheet
A1: Strategic Imperatives
A3: Patient Safety & Quality
A4: Core KPI's | B4: Metric Owner | C4: KPI Definition | D4: AOP 2026 | E4: Column1 | F4: Column2 | G4: Metric nature | H4: Units | I4: Frequency | J4: Target/ Actual | K4: Jan | L4: Feb | M4: Q1'26 | N4: Apr | O4: May | P4: Jun | Q4: Jul | R4: Aug | S4: Sep | T4: Oct | U4: Nov | V4: Dec
A5: =IF('AOP Critical'!B6="","",'AOP Critical'!B6) -> Complaint Closure | B5: =IF('AOP Critical'!C6="","",'AOP Critical'!C6) -> Neena S | C5: =IF('AOP Critical'!D6="","",'AOP Critical'!D6) -> % Complaints Open > 90 days | D5: =IF('AOP Critical'!E6="","",'AOP Critical'!E6) -> 10 | E5: =IF('AOP Critical'!F6="","",'AOP Critical'!F6) | G5: =IF('AOP Critical'!H6="","",'AOP Critical'!H6) -> Lower the better | H5: =IF('AOP Critical'!I6="","",'AOP Critical'!I6) -> % | I5: =IF('AOP Critical'!J6="","",'AOP Critical'!J6) -> Monthly | J5: =IF('AOP Critical'!K6="","",'AOP Critical'!K6) -> T | K5: =IF('AOP Critical'!L6="","",'AOP Critical'!L6) -> 0.08 | L5: =IF('AOP Critical'!M6="","",'AOP Critical'!M6) -> 0.08 | M5: =IF('AOP Critical'!N6="","",'AOP Critical'!N6) -> 0.08 | N5: =IF('AOP Critical'!O6="","",'AOP Critical'!O6) -> 0.07 | ... V5: =IF('AOP Critical'!W6="","",'AOP Critical'!W6) -> 0.05
A6: =IF('AOP Critical'!B6="","",'AOP Critical'!B6) -> Complaint Closure | B6: =IF('AOP Critical'!C6="","",'AOP Critical'!C6) -> Neena S | C6: =IF('AOP Critical'!D6="","",'AOP Critical'!D6) -> % Complaints Open > 90 days | D6: =IF('AOP Critical'!E6="","",'AOP Critical'!E6) -> 10 | E6: =IF('AOP Critical'!F6="","",'AOP Critical'!F6) | G6: =IF('AOP Critical'!H6="","",'AOP Critical'!H6) -> Lower the better | H6: =IF('AOP Critical'!I6="","",'AOP Critical'!I6) -> % | I6: =IF('AOP Critical'!J6="","",'AOP Critical'!J6) -> Monthly | J6: =IF('AOP Critical'!K7="","",'AOP Critical'!K7) -> A | K6: =IF('AOP Critical'!L7="","",'AOP Critical'!L7) -> 0.038 | L6: =IF('AOP Critical'!M7="","",'AOP Critical'!M7) -> 0.038 | M6: =IF('AOP Critical'!N7="","",'AOP Critical'!N7) -> 0.028 | N6: =IF('AOP Critical'!O7="","",'AOP Critical'!O7) -> 0.026 | O6: =IF('AOP Critical'!P7="","",'AOP Critical'!P7) -> 0.026 | P6: =IF('AOP Critical'!Q7="","",'AOP Critical'!Q7) -> 0.03 | Q6: =IF('AOP Critical'!R7="","",'AOP Critical'!R7) -> 0.031 | ... V6: =IF('AOP Critical'!W7="","",'AOP Critical'!W7) -> 0.07
A7: =IF('AOP Critical'!B8="","",'AOP Critical'!B8) -> % of CAPA investgation | B7: =IF('AOP Critical'!C8="","",'AOP Critical'!C8) -> Neena S | C7: =IF('AOP Critical'!D8="","",'AOP Critical'!D8) -> CAPA investigations ≤ 90 days | D7: =IF('AOP Critical'!E8="","",'AOP Critical'!E8) -> 90 | E7: =IF('AOP Critical'!F8="","",'AOP Critical'!F8) | G7: =IF('AOP Critical'!H8="","",'AOP Critical'!H8) -> Higher the better | H7: =IF('AOP Critical'!I8="","",'AOP Critical'!I8) -> % | I7: =IF('AOP Critical'!J8="","",'AOP Critical'!J8) -> Monthly | J7: =IF('AOP Critical'!K8="","",'AOP Critical'!K8) -> T | K7: =IF('AOP Critical'!L8="","",'AOP Critical'!L8) -> 0.9 | L7: =IF('AOP Critical'!M8="","",'AOP Critical'!M8) -> 0.9 | M7: =IF('AOP Critical'!N8="","",'AOP Critical'!N8) -> 0.9 | N7: =IF('AOP Critical'!O8="","",'AOP Critical'!O8) -> 0.9 | ... V7: =IF('AOP Critical'!W8="","",'AOP Critical'!W8)
A8: =IF('AOP Critical'!B8="","",'AOP Critical'!B8) -> % of CAPA investgation | B8: =IF('AOP Critical'!C8="","",'AOP Critical'!C8) -> Neena S | C8: =IF('AOP Critical'!D8="","",'AOP Critical'!D8) -> CAPA investigations ≤ 90 days | D8: =IF('AOP Critical'!E8="","",'AOP Critical'!E8) -> 90 | E8: =IF('AOP Critical'!F8="","",'AOP Critical'!F8) | G8: =IF('AOP Critical'!H8="","",'AOP Critical'!H8) -> Higher the better | H8: =IF('AOP Critical'!I8="","",'AOP Critical'!I8) -> % | I8: =IF('AOP Critical'!J8="","",'AOP Critical'!J8) -> Monthly | J8: =IF('AOP Critical'!K9="","",'AOP Critical'!K9) -> A | K8: =IF('AOP Critical'!L9="","",'AOP Critical'!L9) -> 1 | L8: =IF('AOP Critical'!M9="","",'AOP Critical'!M9) -> 0.75 | M8: =IF('AOP Critical'!N9="","",'AOP Critical'!N9) -> 0.4 | N8: =IF('AOP Critical'!O9="","",'AOP Critical'!O9) -> 0 | O8: =IF('AOP Critical'!P9="","",'AOP Critical'!P9) -> 0 | P8: =IF('AOP Critical'!Q9="","",'AOP Critical'!Q9) -> 0 | Q8: =IF('AOP Critical'!R9="","",'AOP Critical'!R9) -> 1 | ... V8: =IF('AOP Critical'!W9="","",'AOP Critical'!W9)
A9: =IF('AOP Critical'!B10="","",'AOP Critical'!B10) -> # of Corrections & Removals | B9: =IF('AOP Critical'!C10="","",'AOP Critical'!C10) -> Neena S | C9: =IF('AOP Critical'!D10="","",'AOP Critical'!D10) -> C&R Implementation miss per global due date | D9: =IF('AOP Critical'!E10="","",'AOP Critical'!E10) -> 1 | E9: =IF('AOP Critical'!F10="","",'AOP Critical'!F10) | G9: =IF('AOP Critical'!H10="","",'AOP Critical'!H10) -> Lower the better | H9: =IF('AOP Critical'!I10="","",'AOP Critical'!I10) -> No. | I9: =IF('AOP Critical'!J10="","",'AOP Critical'!J10) -> Monthly | J9: =IF('AOP Critical'!K10="","",'AOP Critical'!K10) -> T | K9: =IF('AOP Critical'!L10="","",'AOP Critical'!L10) -> 1 | L9: =IF('AOP Critical'!M10="","",'AOP Critical'!M10) -> 1 | M9: =IF('AOP Critical'!N10="","",'AOP Critical'!N10) -> 1 | N9: =IF('AOP Critical'!O10="","",'AOP Critical'!O10) -> 1 | ... V9: =IF('AOP Critical'!W10="","",'AOP Critical'!W10)
A10: =IF('AOP Critical'!B10="","",'AOP Critical'!B10) -> # of Corrections & Removals | B10: =IF('AOP Critical'!C10="","",'AOP Critical'!C10) -> Neena S | C10: =IF('AOP Critical'!D10="","",'AOP Critical'!D10) -> C&R Implementation miss per global due date | D10: =IF('AOP Critical'!E10="","",'AOP Critical'!E10) -> 1 | E10: =IF('AOP Critical'!F10="","",'AOP Critical'!F10) | G10: =IF('AOP Critical'!H10="","",'AOP Critical'!H10) -> Lower the better | H10: =IF('AOP Critical'!I10="","",'AOP Critical'!I10) -> No. | I10: =IF('AOP Critical'!J10="","",'AOP Critical'!J10) -> Monthly | J10: =IF('AOP Critical'!K11="","",'AOP Critical'!K11) -> A | K10: =IF('AOP Critical'!L11="","",'AOP Critical'!L11) -> 2 | L10: =IF('AOP Critical'!M11="","",'AOP Critical'!M11) -> 1 | M10: =IF('AOP Critical'!N11="","",'AOP Critical'!N11) -> 1 | N10: =IF('AOP Critical'!O11="","",'AOP Critical'!O11) -> 0 | O10: =IF('AOP Critical'!P11="","",'AOP Critical'!P11) -> 0 | P10: =IF('AOP Critical'!Q11="","",'AOP Critical'!Q11) -> 0 | Q10: =IF('AOP Critical'!R11="","",'AOP Critical'!R11) -> 0 | ... V10: =IF('AOP Critical'!W11="","",'AOP Critical'!W11)
A11: =IF('AOP Critical'!B41="","",'AOP Critical'!B41) -> Cost Of Non-Quality as % of Sales | B11: =IF('AOP Critical'!C41="","",'AOP Critical'!C41) -> Neena S | C11: =IF('AOP Critical'!D41="","",'AOP Critical'!D41) -> Cost of FCO, Warranty, Obsolescence, Scrap and Rework. | D11: =IF('AOP Critical'!E41="","",'AOP Critical'!E41) -> TBD | E11: =IF('AOP Critical'!F41="","",'AOP Critical'!F41) -> TBD | G11: =IF('AOP Critical'!H41="","",'AOP Critical'!H41) -> Lower the better | H11: =IF('AOP Critical'!I41="","",'AOP Critical'!I41) -> % | I11: =IF('AOP Critical'!J41="","",'AOP Critical'!J41) -> Monthly | J11: =IF('AOP Critical'!K41="","",'AOP Critical'!K41) -> T | K11: =IF('AOP Critical'!L41="","",'AOP Critical'!L41) -> 0.0191 | L11: =IF('AOP Critical'!M41="","",'AOP Critical'!M41) -> 0.0407 | M11: =IF('AOP Critical'!N41="","",'AOP Critical'!N41) -> 0.0462 | N11: =IF('AOP Critical'!O41="","",'AOP Critical'!O41) -> 0.0386 | ... V11: =IF('AOP Critical'!W41="","",'AOP Critical'!W41) -> 0.0332
A12: =IF('AOP Critical'!B41="","",'AOP Critical'!B41) -> Cost Of Non-Quality as % of Sales | B12: =IF('AOP Critical'!C41="","",'AOP Critical'!C41) -> Neena S | C12: =IF('AOP Critical'!D41="","",'AOP Critical'!D41) -> Cost of FCO, Warranty, Obsolescence, Scrap and Rework. | D12: =IF('AOP Critical'!E41="","",'AOP Critical'!E41) -> TBD | E12: =IF('AOP Critical'!F41="","",'AOP Critical'!F41) -> TBD | G12: =IF('AOP Critical'!H41="","",'AOP Critical'!H41) -> Lower the better | H12: =IF('AOP Critical'!I41="","",'AOP Critical'!I41) -> % | I12: =IF('AOP Critical'!J41="","",'AOP Critical'!J41) -> Monthly | J12: =IF('AOP Critical'!K42="","",'AOP Critical'!K42) -> A | K12: =IF('AOP Critical'!L42="","",'AOP Critical'!L42) -> 0.0092 | L12: =IF('AOP Critical'!M42="","",'AOP Critical'!M42) -> 0.0158 | M12: =IF('AOP Critical'!N42="","",'AOP Critical'!N42) -> 0.0176 | N12: =IF('AOP Critical'!O42="","",'AOP Critical'!O42) -> 0.0158 | O12: =IF('AOP Critical'!P42="","",'AOP Critical'!P42) -> 0.0086 | P12: =IF('AOP Critical'!Q42="","",'AOP Critical'!Q42) -> 0.0127 | Q12: =IF('AOP Critical'!R42="","",'AOP Critical'!R42) -> 0.0133 | ... V12: =IF('AOP Critical'!W42="","",'AOP Critical'!W42)
A13: Customer Focus
A14: Core KPI's | B14: Metric Owner | C14: KPI Definition | D14: AOP 2026 | E14: Column1 | F14: Column2 | G14: Metric nature | H14: Units | I14: Frequency | J14: Target/ Actual | K14: Jan | L14: Feb | M14: Q1'26 | N14: Apr | O14: May | P14: Jun | Q14: Jul | R14: Aug | S14: Sep | T14: Oct | U14: Nov | V14: Dec
A15: =IF('AOP Critical'!B12="","",'AOP Critical'!B12) -> Ontime In Full | B15: =IF('AOP Critical'!C12="","",'AOP Critical'!C12) -> Rupali J | C15: =IF('AOP Critical'!D12="","",'AOP Critical'!D12) -> On Time In Full Z4-Z10 | D15: =IF('AOP Critical'!E12="","",'AOP Critical'!E12) -> 84 | E15: =IF('AOP Critical'!F12="","",'AOP Critical'!F12) | F15: =IF('AOP Critical'!G12="","",'AOP Critical'!G12) | G15: =IF('AOP Critical'!H12="","",'AOP Critical'!H12) -> Higher the better | H15: =IF('AOP Critical'!I12="","",'AOP Critical'!I12) -> % | ... V15: =IF('AOP Critical'!W12="","",'AOP Critical'!W12) -> 0.79
A16: =IF('AOP Critical'!B12="","",'AOP Critical'!B12) -> Ontime In Full | B16: =IF('AOP Critical'!C12="","",'AOP Critical'!C12) -> Rupali J | C16: =IF('AOP Critical'!D12="","",'AOP Critical'!D12) -> On Time In Full Z4-Z10 | D16: =IF('AOP Critical'!E12="","",'AOP Critical'!E12) -> 84 | E16: =IF('AOP Critical'!F12="","",'AOP Critical'!F12) | F16: =IF('AOP Critical'!G12="","",'AOP Critical'!G12) | G16: =IF('AOP Critical'!H12="","",'AOP Critical'!H12) -> Higher the better | H16: =IF('AOP Critical'!I12="","",'AOP Critical'!I12) -> % | I16: =IF('AOP Critical'!J12="","",'AOP Critical'!J12) -> Monthly | J16: =IF('AOP Critical'!K13="","",'AOP Critical'!K13) -> A | K16: =IF('AOP Critical'!L13="","",'AOP Critical'!L13) -> 0.83 | L16: =IF('AOP Critical'!M13="","",'AOP Critical'!M13) -> 0.82 | M16: =IF('AOP Critical'!N13="","",'AOP Critical'!N13) -> 0.81 | N16: =IF('AOP Critical'!O13="","",'AOP Critical'!O13) -> 0.6 | O16: =IF('AOP Critical'!P13="","",'AOP Critical'!P13) -> 0.87 | P16: =IF('AOP Critical'!Q13="","",'AOP Critical'!Q13) -> 0.77 | Q16: =IF('AOP Critical'!R13="","",'AOP Critical'!R13) -> 0.75 | ... V16: =IF('AOP Critical'!W13="","",'AOP Critical'!W13)
A17: =IF('AOP Critical'!B14="","",'AOP Critical'!B14) -> Contract Penetration | B17: =IF('AOP Critical'!C14="","",'AOP Critical'!C14) -> Sangram T | C17: =IF('AOP Critical'!D14="","",'AOP Critical'!D14) -> Increase contract penetration % | D17: =IF('AOP Critical'!E14="","",'AOP Critical'!E14) -> 54.6 | E17: =IF('AOP Critical'!F14="","",'AOP Critical'!F14) | F17: =IF('AOP Critical'!G14="","",'AOP Critical'!G14) | G17: =IF('AOP Critical'!H14="","",'AOP Critical'!H14) -> Higher the better | H17: =IF('AOP Critical'!I14="","",'AOP Critical'!I14) -> % | ... V17: =IF('AOP Critical'!W14="","",'AOP Critical'!W14)
A18: =IF('AOP Critical'!B14="","",'AOP Critical'!B14) -> Contract Penetration | B18: =IF('AOP Critical'!C14="","",'AOP Critical'!C14) -> Sangram T | C18: =IF('AOP Critical'!D14="","",'AOP Critical'!D14) -> Increase contract penetration % | D18: =IF('AOP Critical'!E14="","",'AOP Critical'!E14) -> 54.6 | E18: =IF('AOP Critical'!F14="","",'AOP Critical'!F14) | F18: =IF('AOP Critical'!G14="","",'AOP Critical'!G14) | G18: =IF('AOP Critical'!H14="","",'AOP Critical'!H14) -> Higher the better | H18: =IF('AOP Critical'!I14="","",'AOP Critical'!I14) -> % | I18: =IF('AOP Critical'!J14="","",'AOP Critical'!J14) -> Monthly | J18: =IF('AOP Critical'!K15="","",'AOP Critical'!K15) -> A | K18: =IF('AOP Critical'!L15="","",'AOP Critical'!L15) -> 0.5178 | L18: =IF('AOP Critical'!M15="","",'AOP Critical'!M15) -> 0.541 | M18: =IF('AOP Critical'!N15="","",'AOP Critical'!N15) -> 0.541 | N18: =IF('AOP Critical'!O15="","",'AOP Critical'!O15) -> 0.5397 | O18: =IF('AOP Critical'!P15="","",'AOP Critical'!P15) -> 0.541 | P18: =IF('AOP Critical'!Q15="","",'AOP Critical'!Q15) -> 0.538 | Q18: =IF('AOP Critical'!R15="","",'AOP Critical'!R15) -> 0.536 | ... V18: =IF('AOP Critical'!W15="","",'AOP Critical'!W15)
A19: =IF('AOP Critical'!B49="","",'AOP Critical'!B49) -> Services - Time To System Up (TTSU) | B19: =IF('AOP Critical'!C49="","",'AOP Critical'!C49) -> Sangram T | C19: =IF('AOP Critical'!D49="","",'AOP Critical'!D49) -> % of system down cases back up <48hrs | D19: =IF('AOP Critical'!E49="","",'AOP Critical'!E49) -> 74 | E19: =IF('AOP Critical'!F49="","",'AOP Critical'!F49) -> TBD | F19: =IF('AOP Critical'!G49="","",'AOP Critical'!G49) -> TBD | G19: =IF('AOP Critical'!H49="","",'AOP Critical'!H49) -> Higher the better | H19: =IF('AOP Critical'!I49="","",'AOP Critical'!I49) -> % | ... V19: =IF('AOP Critical'!W49="","",'AOP Critical'!W49) -> 0.74
A20: =IF('AOP Critical'!B49="","",'AOP Critical'!B49) -> Services - Time To System Up (TTSU) | B20: =IF('AOP Critical'!C49="","",'AOP Critical'!C49) -> Sangram T | C20: =IF('AOP Critical'!D49="","",'AOP Critical'!D49) -> % of system down cases back up <48hrs | D20: =IF('AOP Critical'!E49="","",'AOP Critical'!E49) -> 74 | E20: =IF('AOP Critical'!F49="","",'AOP Critical'!F49) -> TBD | F20: =IF('AOP Critical'!G49="","",'AOP Critical'!G49) -> TBD | G20: =IF('AOP Critical'!H49="","",'AOP Critical'!H49) -> Higher the better | H20: =IF('AOP Critical'!I49="","",'AOP Critical'!I49) -> % | I20: =IF('AOP Critical'!J49="","",'AOP Critical'!J49) -> Monthly | J20: =IF('AOP Critical'!K50="","",'AOP Critical'!K50) -> A | K20: =IF('AOP Critical'!L50="","",'AOP Critical'!L50) -> 0.693 | L20: =IF('AOP Critical'!M50="","",'AOP Critical'!M50) -> 0.711 | M20: =IF('AOP Critical'!N50="","",'AOP Critical'!N50) -> 0.725 | N20: =IF('AOP Critical'!O50="","",'AOP Critical'!O50) -> 0.723 | O20: =IF('AOP Critical'!P50="","",'AOP Critical'!P50) -> 0.736 | P20: =IF('AOP Critical'!Q50="","",'AOP Critical'!Q50) -> 0.7415 | Q20: =IF('AOP Critical'!R50="","",'AOP Critical'!R50) -> 0.741 | ... V20: =IF('AOP Critical'!W50="","",'AOP Critical'!W50)
A21: Improve Deliverability & Profitability
A22: Core KPI's | B22: Metric Owner | C22: KPI Definition | D22: AOP 2026 | E22: Column1 | F22: Column2 | G22: Metric nature | H22: Units | I22: Frequency | J22: Target/ Actual | K22: Jan | L22: Feb | M22: Q1'26 | N22: Apr | O22: May | P22: Jun | Q22: Jul | R22: Aug | S22: Sep | T22: Oct | U22: Nov | V22: Dec
A23: =IF('AOP Critical'!B16="","",'AOP Critical'!B16) -> Adjusted EBITA % | B23: =IF('AOP Critical'!C16="","",'AOP Critical'!C16) -> Chetan L | C23: =IF('AOP Critical'!D16="","",'AOP Critical'!D16) -> Adjusted EBIT per comitted 2026 | D23: =IF('AOP Critical'!E16="","",'AOP Critical'!E16) -> AOP | E23: =IF('AOP Critical'!F16="","",'AOP Critical'!F16) | F23: =IF('AOP Critical'!G16="","",'AOP Critical'!G16) | G23: =IF('AOP Critical'!H16="","",'AOP Critical'!H16) -> Higher the better | H23: =IF('AOP Critical'!I16="","",'AOP Critical'!I16) -> % | ... V23: =IF('AOP Critical'!W16="","",'AOP Critical'!W16)
A24: =IF('AOP Critical'!B16="","",'AOP Critical'!B16) -> Adjusted EBITA % | B24: =IF('AOP Critical'!C16="","",'AOP Critical'!C16) -> Chetan L | C24: =IF('AOP Critical'!D16="","",'AOP Critical'!D16) -> Adjusted EBIT per comitted 2026 | D24: =IF('AOP Critical'!E16="","",'AOP Critical'!E16) -> AOP | E24: =IF('AOP Critical'!F16="","",'AOP Critical'!F16) | F24: =IF('AOP Critical'!G16="","",'AOP Critical'!G16) | G24: =IF('AOP Critical'!H16="","",'AOP Critical'!H16) -> Higher the better | H24: =IF('AOP Critical'!I16="","",'AOP Critical'!I16) -> % | I24: =IF('AOP Critical'!J16="","",'AOP Critical'!J16) -> Monthly | J24: =IF('AOP Critical'!K17="","",'AOP Critical'!K17) -> A | K24: =IF('AOP Critical'!L17="","",'AOP Critical'!L17) -> -0.042533115 | L24: =IF('AOP Critical'!M17="","",'AOP Critical'!M17) -> 0.078013175 | M24: =IF('AOP Critical'!N17="","",'AOP Critical'!N17) -> 0.147 | N24: =IF('AOP Critical'!O17="","",'AOP Critical'!O17) -> 0.13678322 | O24: =IF('AOP Critical'!P17="","",'AOP Critical'!P17) -> 0.14558304 | P24: =IF('AOP Critical'!Q17="","",'AOP Critical'!Q17) -> 0.12590494 | Q24: =IF('AOP Critical'!R17="","",'AOP Critical'!R17) -> 0.1071272 | ... V24: =IF('AOP Critical'!W17="","",'AOP Critical'!W17)
A25: =IF('AOP Critical'!B18="","",'AOP Critical'!B18) -> Productivity | B25: =IF('AOP Critical'!C18="","",'AOP Critical'!C18) -> Chetan L | C25: =IF('AOP Critical'!D18="","",'AOP Critical'!D18) -> Monthly Cost Savings | D25: =IF('AOP Critical'!E18="","",'AOP Critical'!E18) -> AOP | E25: =IF('AOP Critical'!F18="","",'AOP Critical'!F18) | F25: =IF('AOP Critical'!G18="","",'AOP Critical'!G18) | G25: =IF('AOP Critical'!H18="","",'AOP Critical'!H18) -> Higher the better | H25: =IF('AOP Critical'!I18="","",'AOP Critical'!I18) -> Mn | ... V25: =IF('AOP Critical'!W18="","",'AOP Critical'!W18)
A26: =IF('AOP Critical'!B18="","",'AOP Critical'!B18) -> Productivity | B26: =IF('AOP Critical'!C18="","",'AOP Critical'!C18) -> Chetan L | C26: =IF('AOP Critical'!D18="","",'AOP Critical'!D18) -> Monthly Cost Savings | D26: =IF('AOP Critical'!E18="","",'AOP Critical'!E18) -> AOP | E26: =IF('AOP Critical'!F18="","",'AOP Critical'!F18) | F26: =IF('AOP Critical'!G18="","",'AOP Critical'!G18) | G26: =IF('AOP Critical'!H18="","",'AOP Critical'!H18) -> Higher the better | H26: =IF('AOP Critical'!I18="","",'AOP Critical'!I18) -> Mn | I26: =IF('AOP Critical'!J18="","",'AOP Critical'!J18) -> Monthly | J26: =IF('AOP Critical'!K19="","",'AOP Critical'!K19) -> A | K26: =IF('AOP Critical'!L19="","",'AOP Critical'!L19) -> 0.25983817 | L26: =IF('AOP Critical'!M19="","",'AOP Critical'!M19) -> 0.38383817 | M26: =IF('AOP Critical'!N19="","",'AOP Critical'!N19) -> 1.1128382 | N26: =IF('AOP Critical'!O19="","",'AOP Critical'!O19) -> 1.3223862 | O26: =IF('AOP Critical'!P19="","",'AOP Critical'!P19) -> 1.6513862 | P26: =IF('AOP Critical'!Q19="","",'AOP Critical'!Q19) -> 2.1303862 | Q26: =IF('AOP Critical'!R19="","",'AOP Critical'!R19) -> 2.6433862 | ... V26: =IF('AOP Critical'!W19="","",'AOP Critical'!W19)
A27: =IF('AOP Critical'!B20="","",'AOP Critical'!B20) -> Inventory MAT sales | B27: =IF('AOP Critical'!C20="","",'AOP Critical'!C20) -> Rupali J | C27: =IF('AOP Critical'!D20="","",'AOP Critical'!D20) -> Inventory as a % MAT sales | D27: =IF('AOP Critical'!E20="","",'AOP Critical'!E20) -> AOP | E27: =IF('AOP Critical'!F20="","",'AOP Critical'!F20) | F27: =IF('AOP Critical'!G20="","",'AOP Critical'!G20) | G27: =IF('AOP Critical'!H20="","",'AOP Critical'!H20) -> Lower the better | H27: =IF('AOP Critical'!I20="","",'AOP Critical'!I20) -> % | ... V27: =IF('AOP Critical'!W20="","",'AOP Critical'!W20)
A28: =IF('AOP Critical'!B20="","",'AOP Critical'!B20) -> Inventory MAT sales | B28: =IF('AOP Critical'!C20="","",'AOP Critical'!C20) -> Rupali J | C28: =IF('AOP Critical'!D20="","",'AOP Critical'!D20) -> Inventory as a % MAT sales | D28: =IF('AOP Critical'!E20="","",'AOP Critical'!E20) -> AOP | E28: =IF('AOP Critical'!F20="","",'AOP Critical'!F20) | F28: =IF('AOP Critical'!G20="","",'AOP Critical'!G20) | G28: =IF('AOP Critical'!H20="","",'AOP Critical'!H20) -> Lower the better | H28: =IF('AOP Critical'!I20="","",'AOP Critical'!I20) -> % | I28: =IF('AOP Critical'!J20="","",'AOP Critical'!J20) -> Monthly | J28: =IF('AOP Critical'!K21="","",'AOP Critical'!K21) -> A | K28: =IF('AOP Critical'!L21="","",'AOP Critical'!L21) -> 0.274 | L28: =IF('AOP Critical'!M21="","",'AOP Critical'!M21) -> 0.299 | M28: =IF('AOP Critical'!N21="","",'AOP Critical'!N21) -> 0.29 | N28: =IF('AOP Critical'!O21="","",'AOP Critical'!O21) -> 0.3 | O28: =IF('AOP Critical'!P21="","",'AOP Critical'!P21) -> 0.31 | P28: =IF('AOP Critical'!Q21="","",'AOP Critical'!Q21) -> 0.29 | Q28: =IF('AOP Critical'!R21="","",'AOP Critical'!R21) -> 0.3 | ... V28: =IF('AOP Critical'!W21="","",'AOP Critical'!W21)
A29: =IF('AOP Critical'!B51="","",'AOP Critical'!B51) -> Profitability - Margin Expansion | B29: =IF('AOP Critical'!C51="","",'AOP Critical'!C51) -> Chetan L | C29: =IF('AOP Critical'!D51="","",'AOP Critical'!D51) -> Driving profitability via margin expansion | D29: =IF('AOP Critical'!E51="","",'AOP Critical'!E51) -> 33.1 | E29: =IF('AOP Critical'!F51="","",'AOP Critical'!F51) -> TBD | F29: =IF('AOP Critical'!G51="","",'AOP Critical'!G51) -> TBD | G29: =IF('AOP Critical'!H51="","",'AOP Critical'!H51) -> Higher the better | H29: =IF('AOP Critical'!I51="","",'AOP Critical'!I51) -> % | ... V29: =IF('AOP Critical'!W51="","",'AOP Critical'!W51)
A30: =IF('AOP Critical'!B51="","",'AOP Critical'!B51) -> Profitability - Margin Expansion | B30: =IF('AOP Critical'!C51="","",'AOP Critical'!C51) -> Chetan L | C30: =IF('AOP Critical'!D51="","",'AOP Critical'!D51) -> Driving profitability via margin expansion | D30: =IF('AOP Critical'!E51="","",'AOP Critical'!E51) -> 33.1 | E30: =IF('AOP Critical'!F51="","",'AOP Critical'!F51) -> TBD | F30: =IF('AOP Critical'!G51="","",'AOP Critical'!G51) -> TBD | G30: =IF('AOP Critical'!H51="","",'AOP Critical'!H51) -> Higher the better | H30: =IF('AOP Critical'!I51="","",'AOP Critical'!I51) -> % | I30: =IF('AOP Critical'!J51="","",'AOP Critical'!J51) -> Monthly | J30: =IF('AOP Critical'!K52="","",'AOP Critical'!K52) -> A | K30: =IF('AOP Critical'!L52="","",'AOP Critical'!L52) -> 0.3659177 | L30: =IF('AOP Critical'!M52="","",'AOP Critical'!M52) -> 0.43346514 | M30: =IF('AOP Critical'!N52="","",'AOP Critical'!N52) -> 0.41319844 | N30: =IF('AOP Critical'!O52="","",'AOP Critical'!O52) -> 0.41195006 | O30: =IF('AOP Critical'!P52="","",'AOP Critical'!P52) -> 0.40747704 | P30: =IF('AOP Critical'!Q52="","",'AOP Critical'!Q52) -> 0.36849551 | Q30: =IF('AOP Critical'!R52="","",'AOP Critical'!R52) -> 0.35573522 | ... V30: =IF('AOP Critical'!W52="","",'AOP Critical'!W52)
A31: Roadmap competitiveness & Innovation agility
A32: Core KPI's | B32: Metric Owner | C32: KPI Definition | D32: AOP 2026 | E32: Column1 | F32: Column2 | G32: Metric nature | H32: Units | I32: Frequency | J32: Target/ Actual | K32: Jan | L32: Feb | M32: Q1'26 | N32: Apr | O32: May | P32: Jun | Q32: Jul | R32: Aug | S32: Sep | T32: Oct | U32: Nov | V32: Dec
A33: =IF('AOP Critical'!B26="","",'AOP Critical'!B26) -> Win Rate | B33: =IF('AOP Critical'!C26="","",'AOP Critical'!C26) -> Sarika P | C33: =IF('AOP Critical'!D26="","",'AOP Critical'!D26) -> (Philips OIT) / (Philips OIT + lost SFDC + not pursuing SFDC) | D33: =IF('AOP Critical'!E26="","",'AOP Critical'!E26) -> 34 | E33: =IF('AOP Critical'!F26="","",'AOP Critical'!F26) | F33: =IF('AOP Critical'!G26="","",'AOP Critical'!G26) | G33: =IF('AOP Critical'!H26="","",'AOP Critical'!H26) -> Higher the better | H33: =IF('AOP Critical'!I26="","",'AOP Critical'!I26) -> % | ... V33: =IF('AOP Critical'!W26="","",'AOP Critical'!W26)
A34: =IF('AOP Critical'!B26="","",'AOP Critical'!B26) -> Win Rate | B34: =IF('AOP Critical'!C26="","",'AOP Critical'!C26) -> Sarika P | C34: =IF('AOP Critical'!D26="","",'AOP Critical'!D26) -> (Philips OIT) / (Philips OIT + lost SFDC + not pursuing SFDC) | D34: =IF('AOP Critical'!E26="","",'AOP Critical'!E26) -> 34 | E34: =IF('AOP Critical'!F26="","",'AOP Critical'!F26) | F34: =IF('AOP Critical'!G26="","",'AOP Critical'!G26) | G34: =IF('AOP Critical'!H26="","",'AOP Critical'!H26) -> Higher the better | H34: =IF('AOP Critical'!I26="","",'AOP Critical'!I26) -> % | I34: =IF('AOP Critical'!J26="","",'AOP Critical'!J26) -> Monthly | J34: =IF('AOP Critical'!K27="","",'AOP Critical'!K27) -> A | K34: =IF('AOP Critical'!L27="","",'AOP Critical'!L27) -> 0.318 | L34: =IF('AOP Critical'!M27="","",'AOP Critical'!M27) -> 0.358 | M34: =IF('AOP Critical'!N27="","",'AOP Critical'!N27) -> 0.415 | N34: =IF('AOP Critical'!O27="","",'AOP Critical'!O27) -> 0.405 | O34: =IF('AOP Critical'!P27="","",'AOP Critical'!P27) -> 0.371 | P34: =IF('AOP Critical'!Q27="","",'AOP Critical'!Q27) -> 0.419 | Q34: =IF('AOP Critical'!R27="","",'AOP Critical'!R27) -> 0.399 | ... V34: =IF('AOP Critical'!W27="","",'AOP Critical'!W27)
A35: =IF('AOP Critical'!B22="","",'AOP Critical'!B22) -> NPI Schedule Adherence | B35: =IF('AOP Critical'!C22="","",'AOP Critical'!C22) -> Shivaraj G | C35: =IF('AOP Critical'!D22="","",'AOP Critical'!D22) -> Dhruv Schedule Adherence | D35: =IF('AOP Critical'!E22="","",'AOP Critical'!E22) -> 90 | E35: =IF('AOP Critical'!F22="","",'AOP Critical'!F22) | F35: =IF('AOP Critical'!G22="","",'AOP Critical'!G22) | G35: =IF('AOP Critical'!H22="","",'AOP Critical'!H22) -> Higher the better | H35: =IF('AOP Critical'!I22="","",'AOP Critical'!I22) -> % | ... V35: =IF('AOP Critical'!W22="","",'AOP Critical'!W22) -> 0.9
A36: =IF('AOP Critical'!B22="","",'AOP Critical'!B22) -> NPI Schedule Adherence | B36: =IF('AOP Critical'!C22="","",'AOP Critical'!C22) -> Shivaraj G | C36: =IF('AOP Critical'!D22="","",'AOP Critical'!D22) -> Dhruv Schedule Adherence | D36: =IF('AOP Critical'!E22="","",'AOP Critical'!E22) -> 90 | E36: =IF('AOP Critical'!F22="","",'AOP Critical'!F22) | F36: =IF('AOP Critical'!G22="","",'AOP Critical'!G22) | G36: =IF('AOP Critical'!H22="","",'AOP Critical'!H22) -> Higher the better | H36: =IF('AOP Critical'!I22="","",'AOP Critical'!I22) -> % | I36: =IF('AOP Critical'!J22="","",'AOP Critical'!J22) -> Monthly | J36: =IF('AOP Critical'!K23="","",'AOP Critical'!K23) -> A | K36: =IF('AOP Critical'!L23="","",'AOP Critical'!L23) -> 0.81 | L36: =IF('AOP Critical'!M23="","",'AOP Critical'!M23) -> 0.78 | M36: =IF('AOP Critical'!N23="","",'AOP Critical'!N23) -> 0.8 | N36: =IF('AOP Critical'!O23="","",'AOP Critical'!O23) -> 0.82 | O36: =IF('AOP Critical'!P23="","",'AOP Critical'!P23) -> 0.795 | P36: =IF('AOP Critical'!Q23="","",'AOP Critical'!Q23) -> 0.86 | Q36: =IF('AOP Critical'!R23="","",'AOP Critical'!R23) -> 0.88 | ... V36: =IF('AOP Critical'!W23="","",'AOP Critical'!W23)
A37: =IF('AOP Critical'!B43="","",'AOP Critical'!B43) -> Competitive Roadmap | B37: =IF('AOP Critical'!C43="","",'AOP Critical'!C43) -> Sarika P | C37: =IF('AOP Critical'!D43="","",'AOP Critical'!D43) -> Roadmap MS% delivery (NPI OIT) | D37: =IF('AOP Critical'!E43="","",'AOP Critical'!E43) -> TBD | E37: =IF('AOP Critical'!F43="","",'AOP Critical'!F43) -> TBD | F37: =IF('AOP Critical'!G43="","",'AOP Critical'!G43) -> TBD | G37: =IF('AOP Critical'!H43="","",'AOP Critical'!H43) -> Higher the better | H37: =IF('AOP Critical'!I43="","",'AOP Critical'!I43) -> % | ... V37: =IF('AOP Critical'!W43="","",'AOP Critical'!W43)
A38: =IF('AOP Critical'!B43="","",'AOP Critical'!B43) -> Competitive Roadmap | B38: =IF('AOP Critical'!C43="","",'AOP Critical'!C43) -> Sarika P | C38: =IF('AOP Critical'!D43="","",'AOP Critical'!D43) -> Roadmap MS% delivery (NPI OIT) | D38: =IF('AOP Critical'!E43="","",'AOP Critical'!E43) -> TBD | E38: =IF('AOP Critical'!F43="","",'AOP Critical'!F43) -> TBD | F38: =IF('AOP Critical'!G43="","",'AOP Critical'!G43) -> TBD | G38: =IF('AOP Critical'!H43="","",'AOP Critical'!H43) -> Higher the better | H38: =IF('AOP Critical'!I43="","",'AOP Critical'!I43) -> % | I38: =IF('AOP Critical'!J43="","",'AOP Critical'!J43) -> Quarterly | J38: =IF('AOP Critical'!K44="","",'AOP Critical'!K44) -> A | K38: =IF('AOP Critical'!L44="","",'AOP Critical'!L44) -> QTR | L38: =IF('AOP Critical'!M44="","",'AOP Critical'!M44) -> QTR | M38: =IF('AOP Critical'!N44="","",'AOP Critical'!N44) -> 0.042 | N38: =IF('AOP Critical'!O44="","",'AOP Critical'!O44) -> QTR | O38: =IF('AOP Critical'!P44="","",'AOP Critical'!P44) -> QTR | P38: =IF('AOP Critical'!Q44="","",'AOP Critical'!Q44) -> 0.04 | Q38: =IF('AOP Critical'!R44="","",'AOP Critical'!R44) -> QTR | ... V38: =IF('AOP Critical'!W44="","",'AOP Critical'!W44)
A39: =IF('AOP Critical'!B45="","",'AOP Critical'!B45) -> Vitality index | B39: =IF('AOP Critical'!C45="","",'AOP Critical'!C45) -> Sarika P | C39: =IF('AOP Critical'!D45="","",'AOP Critical'!D45) -> % of sales from MoS Innovation < 3 years | D39: =IF('AOP Critical'!E45="","",'AOP Critical'!E45) -> TBD | E39: =IF('AOP Critical'!F45="","",'AOP Critical'!F45) -> TBD | F39: =IF('AOP Critical'!G45="","",'AOP Critical'!G45) -> TBD | G39: =IF('AOP Critical'!H45="","",'AOP Critical'!H45) -> Higher the better | H39: =IF('AOP Critical'!I45="","",'AOP Critical'!I45) -> % | ... V39: =IF('AOP Critical'!W45="","",'AOP Critical'!W45)
A40: =IF('AOP Critical'!B45="","",'AOP Critical'!B45) -> Vitality index | B40: =IF('AOP Critical'!C45="","",'AOP Critical'!C45) -> Sarika P | C40: =IF('AOP Critical'!D45="","",'AOP Critical'!D45) -> % of sales from MoS Innovation < 3 years | D40: =IF('AOP Critical'!E45="","",'AOP Critical'!E45) -> TBD | E40: =IF('AOP Critical'!F45="","",'AOP Critical'!F45) -> TBD | F40: =IF('AOP Critical'!G45="","",'AOP Critical'!G45) -> TBD | G40: =IF('AOP Critical'!H45="","",'AOP Critical'!H45) -> Higher the better | H40: =IF('AOP Critical'!I45="","",'AOP Critical'!I45) -> % | I40: =IF('AOP Critical'!J45="","",'AOP Critical'!J45) -> Monthly | J40: =IF('AOP Critical'!K46="","",'AOP Critical'!K46) -> A | K40: =IF('AOP Critical'!L46="","",'AOP Critical'!L46) -> 0.66 | L40: =IF('AOP Critical'!M46="","",'AOP Critical'!M46) -> 0.34 | M40: =IF('AOP Critical'!N46="","",'AOP Critical'!N46) -> 0.41 | N40: =IF('AOP Critical'!O46="","",'AOP Critical'!O46) -> 0.39 | O40: =IF('AOP Critical'!P46="","",'AOP Critical'!P46) -> 0.408 | P40: =IF('AOP Critical'!Q46="","",'AOP Critical'!Q46) -> 0.43 | Q40: =IF('AOP Critical'!R46="","",'AOP Critical'!R46) -> 0.56 | ... V40: =IF('AOP Critical'!W46="","",'AOP Critical'!W46)
A41: =IF('AOP Critical'!B47="","",'AOP Critical'!B47) -> I2M Value Creation | B41: =IF('AOP Critical'!C47="","",'AOP Critical'!C47) -> Shivaraj G | C41: =IF('AOP Critical'!D47="","",'AOP Critical'!D47) -> Development progress (per year, per quarter, %) X Incremental IGM | D41: =IF('AOP Critical'!E47="","",'AOP Critical'!E47) -> TBD | E41: =IF('AOP Critical'!F47="","",'AOP Critical'!F47) -> TBD | F41: =IF('AOP Critical'!G47="","",'AOP Critical'!G47) -> TBD | G41: =IF('AOP Critical'!H47="","",'AOP Critical'!H47) -> Higher the better | H41: =IF('AOP Critical'!I47="","",'AOP Critical'!I47) -> Mn | ... V41: =IF('AOP Critical'!W47="","",'AOP Critical'!W47) -> 67
...

Sheet AOP Critical
B1: Performance of the Month | C1: 46235
A3: MoS Core KPI's 2026 :
A4: ="Current Month-Year " & ":" & TEXT(TODAY(),"YYYY-MM") -> Current Month-Year :2026-10
A5: Strategic Imperatives | B5: Core KPI's | C5: Metric Owner | D5: KPI Definition | E5: AOP 2026 | H5: Metric nature | I5: Units | J5: Frequency | K5: Target/ Actual | L5: Jan | M5: Feb | N5: Q1 | O5: Apr | P5: May | Q5: Q2 | R5: Jul | S5: Aug | T5: Q3 | U5: Oct | V5: Nov | W5: Dec | X5: If reported Red then state Cause | Y5: State Action/s to Cause | Z5: Next update DD-MM | AA5: KPI Definition Link
A6: Patient Safety & Quality | B6: Complaint Closure | C6: Neena S | D6: % Complaints Open > 90 days | E6: 10 | H6: Lower the better | I6: % | J6: Monthly | K6: T | L6: 0.08 | M6: 0.08 | N6: 0.08 | O6: 0.07 | P6: 0.07 | Q6: 0.07 | R6: 0.06 | S6: 0.06 | T6: 0.06 | U6: 0.05 | V6: 0.05 | W6: 0.05 | AA6: # of Complaints KPI
K7: A | L7: 0.038 | M7: 0.038 | N7: 0.028 | O7: 0.026 | P7: 0.026 | Q7: 0.03 | R7: 0.031 | S7: 0.035 | T7: 0.035 | W7: 0.07
B8: % of CAPA investgation | C8: Neena S | D8: CAPA investigations ≤ 90 days | E8: 90 | H8: Higher the better | I8: % | J8: Monthly | K8: T | L8: 0.9 | M8: 0.9 | N8: 0.9 | O8: 0.9 | P8: 0.9 | Q8: 0.9 | R8: 0.9 | S8: 0.9 | T8: 0.9 | AA8: CAPA investigations KPI
K9: A | L9: 1 | M9: 0.75 | N9: 0.4 | O9: 0 | P9: 0 | Q9: 0 | R9: 1 | S9: 1 | T9: 1
B10: # of Corrections & Removals | C10: Neena S | D10: C&R Implementation miss per global due date | E10: 1 | H10: Lower the better | I10: No. | J10: Monthly | K10: T | L10: 1 | M10: 1 | N10: 1 | O10: 1 | P10: 1 | Q10: 1 | R10: 1 | S10: 1 | T10: 1 | AA10: # of C&R KPI
K11: A | L11: 2 | M11: 1 | N11: 1 | O11: 0 | P11: 0 | Q11: 0 | R11: 0 | S11: 0 | T11: 0
A12: Customer Focus | B12: Ontime In Full | C12: Rupali J | D12: On Time In Full Z4-Z10 | E12: 84 | H12: Higher the better | I12: % | J12: Monthly | K12: T | L12: 0.69 | M12: 0.69 | N12: 0.69 | O12: 0.72 | P12: 0.72 | Q12: 0.72 | R12: 0.74 | S12: 0.74 | T12: 0.74 | U12: 0.79 | V12: 0.79 | W12: 0.79 | AA12: OTIF KPI
K13: A | L13: 0.83 | M13: 0.82 | N13: 0.81 | O13: 0.6 | P13: 0.87 | Q13: 0.77 | R13: 0.75 | S13: 0.81 | T13: 0.89
B14: Contract Penetration | C14: Sangram T | D14: Increase contract penetration % | E14: 54.6 | H14: Higher the better | I14: % | J14: Monthly | K14: T | L14: 0.5425 | M14: 0.544 | N14: 0.5455 | O14: 0.547 | P14: 0.5485 | Q14: 0.55 | R14: 0.5515 | S14: 0.5451 | T14: 0.5461 | X14: -0.8% delta Vs AOP. Excluding GRC 0.7% YoY improvement. LATAM renewals improved ITM Sep. Expected turnaround is Q4 2026 (Dec) | Y14: 1) Funnel focus actions driven across regions for renewals. 2) Contract Funnel tracked 90 days before expiry for timely renewals.
K15: A | L15: 0.5178 | M15: 0.541 | N15: 0.541 | O15: 0.5397 | P15: 0.541 | Q15: 0.538 | R15: 0.536 | S15: 0.5363 | T15: 0.5375
A16: Improve Deliverability & Profitability | B16: Adjusted EBITA % | C16: Chetan L | D16: Adjusted EBIT per comitted 2026 | E16: AOP | H16: Higher the better | I16: % | J16: Monthly | K16: T | L16: 0.11774015 | M16: 0.076823633 | N16: 0.074 | O16: 0.099962464 | P16: 0.10384987 | Q16: 0.11814555 | R16: 0.13344842 | S16: 0.1397212 | T16: 0.136 | AA16: Adjusted EBITA KPI
K17: A | L17: -0.042533115 | M17: 0.078013175 | N17: 0.147 | O17: 0.13678322 | P17: 0.14558304 | Q17: 0.12590494 | R17: 0.1071272 | S17: 0.12649724 | T17: 0.147
B18: Productivity | C18: Chetan L | D18: Monthly Cost Savings | E18: AOP | H18: Higher the better | I18: Mn | J18: Monthly | K18: T | L18: 0.224 | M18: 0.358 | N18: 0.797 | O18: 1.041 | P18: 1.155 | Q18: 1.604 | R18: 2.418 | S18: 2.93 | T18: 4.27 | X18: YTD Sept Productivity no's on track.Good Realization from E&E savings of Pune and also a gap reduction of R&D Budget YTD. | Z18: 46108
K19: A | L19: 0.25983817 | M19: 0.38383817 | N19: 1.1128382 | O19: 1.3223862 | P19: 1.6513862 | Q19: 2.1303862 | R19: 2.6433862 | S19: 3.3972232 | T19: 4.5205242
B20: Inventory MAT sales | C20: Rupali J | D20: Inventory as a % MAT sales | E20: AOP | H20: Lower the better | I20: % | J20: Monthly | K20: T | L20: 0.284 | M20: 0.2826 | N20: 0.29 | O20: 0.29 | P20: 0.27 | Q20: 0.26 | R20: 0.24 | S20: 0.23 | T20: 0.25 | X20: Market inventory : 7.7 M above AOP . Growth : + 1M Namibia tender EU +1.2 M above AOP driven delayed Demo liquidation , NAM 0.5 M above AOP , UIPE effect increased leading to 10M increase in Mrkt inventory ( Aug reported at 31% against AOP 59% ) | Y20: 1. NAR :AOP accelator program launched to improve OIT to rev conversion. 2. EU : Demo liquidation plan aligned toward Q4 to maximise OIT in Q3. 3. Growth: Namibia tender conversion in Q4 4. UIEP : COE team to analyse the difference and accurate capturing in AOP 2027 | AA20: Inventory as a % MAT sales KPI
K21: A | L21: 0.274 | M21: 0.299 | N21: 0.29 | O21: 0.3 | P21: 0.31 | Q21: 0.29 | R21: 0.3 | S21: 0.3 | T21: 0.27
A22: Roadmap competitiveness & Innovation agility | B22: NPI Schedule Adherence | C22: Shivaraj G | D22: Dhruv Schedule Adherence | E22: 90 | H22: Higher the better | I22: % | J22: Monthly | K22: T | L22: 0.9 | M22: 0.9 | N22: 0.9 | O22: 0.9 | P22: 0.9 | Q22: 0.9 | R22: 0.9 | S22: 0.9 | T22: 0.9 | U22: 0.9 | V22: 0.9 | W22: 0.9 | Z22: 46257
K23: A | L23: 0.81 | M23: 0.78 | N23: 0.8 | O23: 0.82 | P23: 0.795 | Q23: 0.86 | R23: 0.88 | S23: 0.94 | T23: 0.94
A24: Drive growth through Commercial Excellence | B24: Implied Market Share Gain | C24: Sarika P | D24: Implied Market Share Gain (ITQ) | E24: TBD | F24: TBD | G24: TBD | H24: Higher the better | I24: % | J24: Quarterly | K24: T | N24: 0.104 | O24: QTR | P24: QTR | Q24: 0.118 | R24: QTR | S24: QTR | T24: QTR | AA24: Win Rate
K25: A | L25: QTR | M25: QTR | N25: 0.115 | O25: QTR | P25: QTR | Q25: 0.12 | R25: QTR | S25: QTR | T25: QTR
B26: Win Rate | C26: Sarika P | D26: (Philips OIT) / (Philips OIT + lost SFDC + not pursuing SFDC) | E26: 34 | H26: Higher the better | I26: % | J26: Monthly | K26: T | L26: 0.34 | M26: 0.34 | N26: 0.34 | O26: 0.34 | P26: 0.34 | Q26: 0.34 | R26: 0.34 | S26: 0.34 | T26: 0.34 | AA26: Implied Market Share Gain KPI
K27: A | L27: 0.318 | M27: 0.358 | N27: 0.415 | O27: 0.405 | P27: 0.371 | Q27: 0.419 | R27: 0.399 | S27: 0.412 | T27: 0.423
B28: Order Intake Growth | C28: Chetan L | D28: OIT Growth % (EQ) | E28: AOP | H28: Higher the better | I28: % | J28: Monthly | K28: T | L28: 0.036951551 | M28: 0.43621586 | N28: 0.069838697 | O28: 0.2184354 | P28: 0.20239261 | Q28: 0.29754592 | R28: 0.26300518 | S28: 0.30756202 | T28: 0.381 | X28: EQ OIT YTD Sep lower by 0.2M, which is mainly coming by NAR -4.4M, EU -3.7M however Growth supported by over-drive +7.9M | AA28: OIT (Equipment + Service)
K29: A | L29: -0.21537837 | M29: 0.274 | N29: 0.17957 | O29: 0.24020099 | P29: 0.12891206 | Q29: 0.37665227 | R29: 0.26390639 | S29: 0.28426058 | T29: 0.378
C30: Chetan L | D30: OIT Growth % (CS) | E30: AOP | H30: Higher the better | I30: % | J30: Monthly | K30: T | L30: 0.359 | M30: 0.098925322 | N30: 0.11712228 | O30: 0.1581 | P30: 0.151 | Q30: 0.12551463 | R30: 0.10280226 | S30: 0.135 | T30: 0.116
K31: A | L31: 0.325 | M31: 0.19016698 | N31: 0.14313043 | O31: 0.2399 | P31: 0.206 | Q31: 0.15714974 | R31: 0.10382365 | S31: 0.151 | T31: 0.178
B32: Comparable Sales | C32: Rupali J | D32: Monthly Sales recognized (EQ) | E32: AOP | H32: Higher the better | I32: Mn | J32: Monthly | K32: T | L32: 8.6903038 | M32: 14.05 | N32: 24.17907 | O32: 33.551318 | P32: 41.44285 | Q32: 60.823965 | R32: 72.6 | S32: 82.449704 | T32: 97.4 | X32: Current OOH does not support FY revnue plan. OOH is 117 M agaist AOP of 141M .B&B 24 M B&B required to meet FY AOP. | Y32: Drive B&B OIT NAR : 5 M , EU: 8.5M , Growth : 7.6 | AA32: CSG % KPI
K33: A | L33: 4.05 | M33: 9.7989724 | N33: 25.313448 | O33: 31.452557 | P33: 41.128123 | Q33: 55.164575 | R33: 61.94029 | S33: 72.779408 | T33: 91.2
A34: Environmental, Social & Governance | B34: Impact Index | C34: Shivaraj G | D34: ESG Index, ESG >= 90% | E34: 90 | H34: Higher the better | I34: % | J34: Quarterly | K34: T | N34: 0.9 | Q34: 0.9 | T34: 0.9 | W34: 0.9 | Y34: Growth | AA34: Impact Index KPI
K35: A | L35: QTR | M35: QTR | N35: 1 | O35: QTR | P35: QTR | Q35: 0.962 | R35: QTR | S35: QTR | T35: 0.913
B36: Employee Engagement | C36: Lakshmi M | D36: EES >= 83 % | E36: 83 | H36: Higher the better | I36: % | J36: Half yearly | K36: T | O36: 0.83 | Q36: 0.83 | X36: EES scores are out! It is a balanced story. We are better than H1 2025 but slightly worse than H2 2025 | Y36: CS has hit it out of the park.Quality dipped from 100% but still highest, Marketing is holding but at low scores. R&D has dropped some big numbers. | AA36: Employee Engagement KPI
K37: A | L37: HY | M37: HY | N37: HY | O37: 0.79 | P37: HY | Q37: 0.79 | R37: HY | T37: HY
A39: MoS Value Levers 2026 - 2028:
A40: Strategic Imperatives | B40: Value Levers | C40: Metric Owner | D40: KPI Definition | E40: AOP 2026 | F40: AOP 2027 | G40: AOP 2028 | H40: Metric nature | I40: Units | J40: Frequency | K40: Target/ Actual | L40: Jan | M40: Feb | N40: Mar | O40: Apr | P40: May | Q40: June | R40: Jul | S40: Aug | T40: Sep | U40: Oct | V40: Nov | W40: Dec | X40: If reported Red then state Cause | Y40: State Action/s to Cause | Z40: Next update DD-MM | AA40: KPI Definition Link
A41: Patient Safety & Quality | B41: Cost Of Non-Quality as % of Sales | C41: Neena S | D41: Cost of FCO, Warranty, Obsolescence, Scrap and Rework. | E41: TBD | F41: TBD | G41: TBD | H41: Lower the better | I41: % | J41: Monthly | K41: T | L41: 0.0191 | M41: 0.0407 | N41: 0.0462 | O41: 0.0386 | P41: 0.0353 | Q41: 0.0271 | R41: 0.0251 | S41: 0.0241 | T41: 0.0316 | U41: 0.0311 | V41: 0.0357 | W41: 0.0332 | AA41: Cost Of Non-Quality as % of Sales
K42: A | L42: 0.0092 | M42: 0.0158 | N42: 0.0176 | O42: 0.0158 | P42: 0.0086 | Q42: 0.0127 | R42: 0.0133 | S42: 0.0139 | T42: 0.017
...
